Workbook

Sheet README
A1: Video Game Sales -- Portfolio Project
A2: Data analyst portfolio piece | Built in Excel (openpyxl + native pivot tables)
A4: Data Source
A5: "Video Game Sales with Ratings" -- Kaggle dataset by rush4ratio (Vgchartz sales data merged with Metacritic critic/user scores). https://www.kaggle.com/datasets/rush4ratio/video-game-sales-with-ratings
A6: Used in full: 16,717 titles, 1980-2020 (sparse before ~1994 and after 2016). Roughly half the titles have no Metacritic score -- left blank rather than zero-filled, and every AVERAGEIFS/SUMIFS formula in this workbook is checked to confirm it handles those blanks correctly rather than silently treating a missing score as a real value.
A8: Why this dataset
A9: Real-world messiness (missing review scores, a handful of duplicate title/platform rows, sparse tail years) without being chaotic -- a realistic test of whether formulas degrade gracefully instead of just looking right on clean rows.
A11: Technique Map
A12: Technique / Function | B12: Sheet | C12: Cell(s) | D12: Purpose
A13: Text concatenation (&) | B13: Raw Data | C13: Q2 (NamePlatformKey) | D13: Composite key for text-field lookups.
A14: SUMPRODUCT (row finder) | B14: Genre Insights | C14: F5:F16 | D14: Multiplies boolean + ROW() arrays to find a matching row without an array-entered formula.
A15: INDEX/MATCH | B15: Game Lookup | C15: C8:C11 | D15: Returns text fields (Genre, Publisher, Developer, Rating) for the selected title.
A16: SUMIFS (as a 2-criteria lookup) | B16: Game Lookup | C16: C12:C21 | D16: Returns numeric fields without needing a helper key.
A17: COUNTIF / COUNTIFS | B17: Game Lookup, Genre Insights | C17: various | D17: Counts matching rows; also flags 'No data' instead of a false 0.
A18: SUMIF / AVERAGEIFS | B18: Genre Insights, Sales Trends | C18: various | D18: Totals and averages grouped by Genre, Year, or Publisher.
A19: MAXIFS | B19: Genre Insights | C19: F5:F16 | D19: Finds each genre's single highest Global Sales figure, feeding the SUMPRODUCT row finder above.
A20: Native Pivot Table | B20: Genre Insights | C20: H4 | D20: Sum of Global Sales cross-tabbed by Genre x Rating.
A21: Scatter Chart | B21: Genre Insights | C21: below table | D21: Plots avg critic score vs. total sales, one point per genre.
A22: Line Chart | B22: Sales Trends | C22: F4 | D22: Industry-wide global sales by release year.
A23: Conditional formatting (color scale) | B23: Sales Trends | C23: C18:C27 | D23: Highlights top publishers by total sales.
A26: Tip: click any formula cell across this workbook -- cells with a small red corner marker have a comment explaining the technique used, in addition to this map.

Sheet Raw Data
A1: Name | B1: Platform | C1: Year_of_Release | D1: Genre | E1: Publisher | F1: NA_Sales | G1: EU_Sales | H1: JP_Sales | I1: Other_Sales | J1: Global_Sales | K1: Critic_Score | L1: Critic_Count | M1: User_Score | N1: User_Count | O1: Developer | P1: Rating | Q1: NamePlatformKey
A2: Wii Sports | B2: Wii | C2: 2006 | D2: Sports | E2: Nintendo | F2: 41.36 | G2: 28.96 | H2: 3.77 | I2: 8.45 | J2: 82.53 | K2: 76 | L2: 51 | M2: 8 | N2: 322 | O2: Nintendo | P2: E | Q2: =A2&"|"&B2 -> Wii Sports|Wii
A3: Super Mario Bros. | B3: NES | C3: 1985 | D3: Platform | E3: Nintendo | F3: 29.08 | G3: 3.58 | H3: 6.81 | I3: 0.77 | J3: 40.24 | Q3: =A3&"|"&B3 -> Super Mario Bros.|NES
A4: Mario Kart Wii | B4: Wii | C4: 2008 | D4: Racing | E4: Nintendo | F4: 15.68 | G4: 12.76 | H4: 3.79 | I4: 3.29 | J4: 35.52 | K4: 82 | L4: 73 | M4: 8.3 | N4: 709 | O4: Nintendo | P4: E | Q4: =A4&"|"&B4 -> Mario Kart Wii|Wii
A5: Wii Sports Resort | B5: Wii | C5: 2009 | D5: Sports | E5: Nintendo | F5: 15.61 | G5: 10.93 | H5: 3.28 | I5: 2.95 | J5: 32.77 | K5: 80 | L5: 73 | M5: 8 | N5: 192 | O5: Nintendo | P5: E | Q5: =A5&"|"&B5 -> Wii Sports Resort|Wii
A6: Pokemon Red/Pokemon Blue | B6: GB | C6: 1996 | D6: Role-Playing | E6: Nintendo | F6: 11.27 | G6: 8.89 | H6: 10.22 | I6: 1 | J6: 31.37 | Q6: =A6&"|"&B6 -> Pokemon Red/Pokemon Blue|GB
A7: Tetris | B7: GB | C7: 1989 | D7: Puzzle | E7: Nintendo | F7: 23.2 | G7: 2.26 | H7: 4.22 | I7: 0.58 | J7: 30.26 | Q7: =A7&"|"&B7 -> Tetris|GB
A8: New Super Mario Bros. | B8: DS | C8: 2006 | D8: Platform | E8: Nintendo | F8: 11.28 | G8: 9.14 | H8: 6.5 | I8: 2.88 | J8: 29.8 | K8: 89 | L8: 65 | M8: 8.5 | N8: 431 | O8: Nintendo | P8: E | Q8: =A8&"|"&B8 -> New Super Mario Bros.|DS
A9: Wii Play | B9: Wii | C9: 2006 | D9: Misc | E9: Nintendo | F9: 13.96 | G9: 9.18 | H9: 2.93 | I9: 2.84 | J9: 28.92 | K9: 58 | L9: 41 | M9: 6.6 | N9: 129 | O9: Nintendo | P9: E | Q9: =A9&"|"&B9 -> Wii Play|Wii
A10: New Super Mario Bros. Wii | B10: Wii | C10: 2009 | D10: Platform | E10: Nintendo | F10: 14.44 | G10: 6.94 | H10: 4.7 | I10: 2.24 | J10: 28.32 | K10: 87 | L10: 80 | M10: 8.4 | N10: 594 | O10: Nintendo | P10: E | Q10: =A10&"|"&B10 -> New Super Mario Bros. Wii|Wii
A11: Duck Hunt | B11: NES | C11: 1984 | D11: Shooter | E11: Nintendo | F11: 26.93 | G11: 0.63 | H11: 0.28 | I11: 0.47 | J11: 28.31 | Q11: =A11&"|"&B11 -> Duck Hunt|NES
A12: Nintendogs | B12: DS | C12: 2005 | D12: Simulation | E12: Nintendo | F12: 9.05 | G12: 10.95 | H12: 1.93 | I12: 2.74 | J12: 24.67 | Q12: =A12&"|"&B12 -> Nintendogs|DS
A13: Mario Kart DS | B13: DS | C13: 2005 | D13: Racing | E13: Nintendo | F13: 9.71 | G13: 7.47 | H13: 4.13 | I13: 1.9 | J13: 23.21 | K13: 91 | L13: 64 | M13: 8.6 | N13: 464 | O13: Nintendo | P13: E | Q13: =A13&"|"&B13 -> Mario Kart DS|DS
A14: Pokemon Gold/Pokemon Silver | B14: GB | C14: 1999 | D14: Role-Playing | E14: Nintendo | F14: 9 | G14: 6.18 | H14: 7.2 | I14: 0.71 | J14: 23.1 | Q14: =A14&"|"&B14 -> Pokemon Gold/Pokemon Silver|GB
A15: Wii Fit | B15: Wii | C15: 2007 | D15: Sports | E15: Nintendo | F15: 8.92 | G15: 8.03 | H15: 3.6 | I15: 2.15 | J15: 22.7 | K15: 80 | L15: 63 | M15: 7.7 | N15: 146 | O15: Nintendo | P15: E | Q15: =A15&"|"&B15 -> Wii Fit|Wii
A16: Kinect Adventures! | B16: X360 | C16: 2010 | D16: Misc | E16: Microsoft Game Studios | F16: 15 | G16: 4.89 | H16: 0.24 | I16: 1.69 | J16: 21.81 | K16: 61 | L16: 45 | M16: 6.3 | N16: 106 | O16: Good Science Studio | P16: E | Q16: =A16&"|"&B16 -> Kinect Adventures!|X360
A17: Wii Fit Plus | B17: Wii | C17: 2009 | D17: Sports | E17: Nintendo | F17: 9.01 | G17: 8.49 | H17: 2.53 | I17: 1.77 | J17: 21.79 | K17: 80 | L17: 33 | M17: 7.4 | N17: 52 | O17: Nintendo | P17: E | Q17: =A17&"|"&B17 -> Wii Fit Plus|Wii
A18: Grand Theft Auto V | B18: PS3 | C18: 2013 | D18: Action | E18: Take-Two Interactive | F18: 7.02 | G18: 9.09 | H18: 0.98 | I18: 3.96 | J18: 21.04 | K18: 97 | L18: 50 | M18: 8.2 | N18: 3994 | O18: Rockstar North | P18: M | Q18: =A18&"|"&B18 -> Grand Theft Auto V|PS3
A19: Grand Theft Auto: San Andreas | B19: PS2 | C19: 2004 | D19: Action | E19: Take-Two Interactive | F19: 9.43 | G19: 0.4 | H19: 0.41 | I19: 10.57 | J19: 20.81 | K19: 95 | L19: 80 | M19: 9 | N19: 1588 | O19: Rockstar North | P19: M | Q19: =A19&"|"&B19 -> Grand Theft Auto: San Andreas|PS2
A20: Super Mario World | B20: SNES | C20: 1990 | D20: Platform | E20: Nintendo | F20: 12.78 | G20: 3.75 | H20: 3.54 | I20: 0.55 | J20: 20.61 | Q20: =A20&"|"&B20 -> Super Mario World|SNES
A21: Brain Age: Train Your Brain in Minutes a Day | B21: DS | C21: 2005 | D21: Misc | E21: Nintendo | F21: 4.74 | G21: 9.2 | H21: 4.16 | I21: 2.04 | J21: 20.15 | K21: 77 | L21: 58 | M21: 7.9 | N21: 50 | O21: Nintendo | P21: E | Q21: =A21&"|"&B21 -> Brain Age: Train Your Brain in Minutes a Day|DS
A22: Pokemon Diamond/Pokemon Pearl | B22: DS | C22: 2006 | D22: Role-Playing | E22: Nintendo | F22: 6.38 | G22: 4.46 | H22: 6.04 | I22: 1.36 | J22: 18.25 | Q22: =A22&"|"&B22 -> Pokemon Diamond/Pokemon Pearl|DS
A23: Super Mario Land | B23: GB | C23: 1989 | D23: Platform | E23: Nintendo | F23: 10.83 | G23: 2.71 | H23: 4.18 | I23: 0.42 | J23: 18.14 | Q23: =A23&"|"&B23 -> Super Mario Land|GB
A24: Super Mario Bros. 3 | B24: NES | C24: 1988 | D24: Platform | E24: Nintendo | F24: 9.54 | G24: 3.44 | H24: 3.84 | I24: 0.46 | J24: 17.28 | Q24: =A24&"|"&B24 -> Super Mario Bros. 3|NES
A25: Grand Theft Auto V | B25: X360 | C25: 2013 | D25: Action | E25: Take-Two Interactive | F25: 9.66 | G25: 5.14 | H25: 0.06 | I25: 1.41 | J25: 16.27 | K25: 97 | L25: 58 | M25: 8.1 | N25: 3711 | O25: Rockstar North | P25: M | Q25: =A25&"|"&B25 -> Grand Theft Auto V|X360
A26: Grand Theft Auto: Vice City | B26: PS2 | C26: 2002 | D26: Action | E26: Take-Two Interactive | F26: 8.41 | G26: 5.49 | H26: 0.47 | I26: 1.78 | J26: 16.15 | K26: 95 | L26: 62 | M26: 8.7 | N26: 730 | O26: Rockstar North | P26: M | Q26: =A26&"|"&B26 -> Grand Theft Auto: Vice City|PS2
A27: Pokemon Ruby/Pokemon Sapphire | B27: GBA | C27: 2002 | D27: Role-Playing | E27: Nintendo | F27: 6.06 | G27: 3.9 | H27: 5.38 | I27: 0.5 | J27: 15.85 | Q27: =A27&"|"&B27 -> Pokemon Ruby/Pokemon Sapphire|GBA
A28: Brain Age 2: More Training in Minutes a Day | B28: DS | C28: 2005 | D28: Puzzle | E28: Nintendo | F28: 3.43 | G28: 5.35 | H28: 5.32 | I28: 1.18 | J28: 15.29 | K28: 77 | L28: 37 | M28: 7.1 | N28: 19 | O28: Nintendo | P28: E | Q28: =A28&"|"&B28 -> Brain Age 2: More Training in Minutes a Day|DS
A29: Pokemon Black/Pokemon White | B29: DS | C29: 2010 | D29: Role-Playing | E29: Nintendo | F29: 5.51 | G29: 3.17 | H29: 5.65 | I29: 0.8 | J29: 15.14 | Q29: =A29&"|"&B29 -> Pokemon Black/Pokemon White|DS
A30: Gran Turismo 3: A-Spec | B30: PS2 | C30: 2001 | D30: Racing | E30: Sony Computer Entertainment | F30: 6.85 | G30: 5.09 | H30: 1.87 | I30: 1.16 | J30: 14.98 | K30: 95 | L30: 54 | M30: 8.4 | N30: 314 | O30: Polyphony Digital | P30: E | Q30: =A30&"|"&B30 -> Gran Turismo 3: A-Spec|PS2
A31: Call of Duty: Modern Warfare 3 | B31: X360 | C31: 2011 | D31: Shooter | E31: Activision | F31: 9.04 | G31: 4.24 | H31: 0.13 | I31: 1.32 | J31: 14.73 | K31: 88 | L31: 81 | M31: 3.4 | N31: 8713 | O31: Infinity Ward, Sledgehammer Games | P31: M | Q31: =A31&"|"&B31 -> Call of Duty: Modern Warfare 3|X360
A32: Pokémon Yellow: Special Pikachu Edition | B32: GB | C32: 1998 | D32: Role-Playing | E32: Nintendo | F32: 5.89 | G32: 5.04 | H32: 3.12 | I32: 0.59 | J32: 14.64 | Q32: =A32&"|"&B32 -> Pokémon Yellow: Special Pikachu Edition|GB
A33: Call of Duty: Black Ops 3 | B33: PS4 | C33: 2015 | D33: Shooter | E33: Activision | F33: 6.03 | G33: 5.86 | H33: 0.36 | I33: 2.38 | J33: 14.63 | Q33: =A33&"|"&B33 -> Call of Duty: Black Ops 3|PS4
A34: Call of Duty: Black Ops | B34: X360 | C34: 2010 | D34: Shooter | E34: Activision | F34: 9.7 | G34: 3.68 | H34: 0.11 | I34: 1.13 | J34: 14.61 | K34: 87 | L34: 89 | M34: 6.3 | N34: 1454 | O34: Treyarch | P34: M | Q34: =A34&"|"&B34 -> Call of Duty: Black Ops|X360
A35: Pokemon X/Pokemon Y | B35: 3DS | C35: 2013 | D35: Role-Playing | E35: Nintendo | F35: 5.28 | G35: 4.19 | H35: 4.35 | I35: 0.78 | J35: 14.6 | Q35: =A35&"|"&B35 -> Pokemon X/Pokemon Y|3DS
A36: Call of Duty: Black Ops II | B36: PS3 | C36: 2012 | D36: Shooter | E36: Activision | F36: 4.99 | G36: 5.73 | H36: 0.65 | I36: 2.42 | J36: 13.79 | K36: 83 | L36: 21 | M36: 5.3 | N36: 922 | O36: Treyarch | P36: M | Q36: =A36&"|"&B36 -> Call of Duty: Black Ops II|PS3
A37: Call of Duty: Black Ops II | B37: X360 | C37: 2012 | D37: Shooter | E37: Activision | F37: 8.25 | G37: 4.24 | H37: 0.07 | I37: 1.12 | J37: 13.67 | K37: 83 | L37: 73 | M37: 4.8 | N37: 2256 | O37: Treyarch | P37: M | Q37: =A37&"|"&B37 -> Call of Duty: Black Ops II|X360
A38: Call of Duty: Modern Warfare 2 | B38: X360 | C38: 2009 | D38: Shooter | E38: Activision | F38: 8.52 | G38: 3.59 | H38: 0.08 | I38: 1.28 | J38: 13.47 | K38: 94 | L38: 100 | M38: 6.3 | N38: 2698 | O38: Infinity Ward | P38: M | Q38: =A38&"|"&B38 -> Call of Duty: Modern Warfare 2|X360
A39: Call of Duty: Modern Warfare 3 | B39: PS3 | C39: 2011 | D39: Shooter | E39: Activision | F39: 5.54 | G39: 5.73 | H39: 0.49 | I39: 1.57 | J39: 13.32 | K39: 88 | L39: 39 | M39: 3.2 | N39: 5234 | O39: Infinity Ward, Sledgehammer Games | P39: M | Q39: =A39&"|"&B39 -> Call of Duty: Modern Warfare 3|PS3
A40: Grand Theft Auto III | B40: PS2 | C40: 2001 | D40: Action | E40: Take-Two Interactive | F40: 6.99 | G40: 4.51 | H40: 0.3 | I40: 1.3 | J40: 13.1 | K40: 97 | L40: 56 | M40: 8.5 | N40: 664 | O40: DMA Design | P40: M | Q40: =A40&"|"&B40 -> Grand Theft Auto III|PS2
...

Sheet Game Lookup
A1: GAME LOOKUP TOOL
A2: Type a game title and platform below. Numeric fields use SUMIFS; text fields use INDEX/MATCH.
B4: Game Title: | C4: Wii Sports
B5: Platform: | C5: Wii
B7: Field | C7: Value
B8: Genre | C8: =IFERROR(INDEX('Raw Data'!$D:$D,MATCH($C$4&"|"&$C$5,'Raw Data'!$Q:$Q,0)),"Not found") -> Sports
B9: Publisher | C9: =IFERROR(INDEX('Raw Data'!$E:$E,MATCH($C$4&"|"&$C$5,'Raw Data'!$Q:$Q,0)),"Not found") -> Nintendo
B10: Developer | C10: =IFERROR(INDEX('Raw Data'!$O:$O,MATCH($C$4&"|"&$C$5,'Raw Data'!$Q:$Q,0)),"Not found") -> Nintendo
B11: Rating | C11: =IFERROR(INDEX('Raw Data'!$P:$P,MATCH($C$4&"|"&$C$5,'Raw Data'!$Q:$Q,0)),"Not found") -> E
B12: Year of Release | C12: =IF(COUNTIFS('Raw Data'!$A:$A,$C$4,'Raw Data'!$B:$B,$C$5,'Raw Data'!$C:$C,"<>")=0,"No data",SUMIFS('Raw Data'!$C:$C,'Raw Data'!$A:$A,$C$4,'Raw Data'!$B:$B,$C$5)) -> 2006
B13: NA Sales ($M) | C13: =IF(COUNTIFS('Raw Data'!$A:$A,$C$4,'Raw Data'!$B:$B,$C$5,'Raw Data'!$F:$F,"<>")=0,"No data",SUMIFS('Raw Data'!$F:$F,'Raw Data'!$A:$A,$C$4,'Raw Data'!$B:$B,$C$5)) -> 41.36
B14: EU Sales ($M) | C14: =IF(COUNTIFS('Raw Data'!$A:$A,$C$4,'Raw Data'!$B:$B,$C$5,'Raw Data'!$G:$G,"<>")=0,"No data",SUMIFS('Raw Data'!$G:$G,'Raw Data'!$A:$A,$C$4,'Raw Data'!$B:$B,$C$5)) -> 28.96
B15: JP Sales ($M) | C15: =IF(COUNTIFS('Raw Data'!$A:$A,$C$4,'Raw Data'!$B:$B,$C$5,'Raw Data'!$H:$H,"<>")=0,"No data",SUMIFS('Raw Data'!$H:$H,'Raw Data'!$A:$A,$C$4,'Raw Data'!$B:$B,$C$5)) -> 3.77
B16: Other Sales ($M) | C16: =IF(COUNTIFS('Raw Data'!$A:$A,$C$4,'Raw Data'!$B:$B,$C$5,'Raw Data'!$I:$I,"<>")=0,"No data",SUMIFS('Raw Data'!$I:$I,'Raw Data'!$A:$A,$C$4,'Raw Data'!$B:$B,$C$5)) -> 8.45
B17: Global Sales ($M) | C17: =IF(COUNTIFS('Raw Data'!$A:$A,$C$4,'Raw Data'!$B:$B,$C$5,'Raw Data'!$J:$J,"<>")=0,"No data",SUMIFS('Raw Data'!$J:$J,'Raw Data'!$A:$A,$C$4,'Raw Data'!$B:$B,$C$5)) -> 82.53
B18: Critic Score | C18: =IF(COUNTIFS('Raw Data'!$A:$A,$C$4,'Raw Data'!$B:$B,$C$5,'Raw Data'!$K:$K,"<>")=0,"No data",SUMIFS('Raw Data'!$K:$K,'Raw Data'!$A:$A,$C$4,'Raw Data'!$B:$B,$C$5)) -> 76
B19: Critic Count | C19: =IF(COUNTIFS('Raw Data'!$A:$A,$C$4,'Raw Data'!$B:$B,$C$5,'Raw Data'!$L:$L,"<>")=0,"No data",SUMIFS('Raw Data'!$L:$L,'Raw Data'!$A:$A,$C$4,'Raw Data'!$B:$B,$C$5)) -> 51
B20: User Score | C20: =IF(COUNTIFS('Raw Data'!$A:$A,$C$4,'Raw Data'!$B:$B,$C$5,'Raw Data'!$M:$M,"<>")=0,"No data",SUMIFS('Raw Data'!$M:$M,'Raw Data'!$A:$A,$C$4,'Raw Data'!$B:$B,$C$5)) -> 8
B21: User Count | C21: =IF(COUNTIFS('Raw Data'!$A:$A,$C$4,'Raw Data'!$B:$B,$C$5,'Raw Data'!$N:$N,"<>")=0,"No data",SUMIFS('Raw Data'!$N:$N,'Raw Data'!$A:$A,$C$4,'Raw Data'!$B:$B,$C$5)) -> 322

Sheet Genre Insights
A1: GENRE INSIGHTS
A2: Critical reception vs. commercial performance, by genre.
A4: Genre | B4: Games | C4: Total Global Sales ($M) | D4: Avg Critic Score | E4: Avg User Score (x10) | F4: Best Seller | H4: Filter
A5: Action | B5: =COUNTIF('Raw Data'!$D:$D,$A5) -> 3370 | C5: =SUMIF('Raw Data'!$D:$D,$A5,'Raw Data'!$J:$J) -> 1745.27 | D5: =AVERAGEIFS('Raw Data'!$K:$K,'Raw Data'!$D:$D,$A5) -> 66.629101 | E5: =AVERAGEIFS('Raw Data'!$M:$M,'Raw Data'!$D:$D,$A5)*10 -> 70.540437 | F5: =IFERROR(INDEX('Raw Data'!$A:$A,SUMPRODUCT(('Raw Data'!$D$2:$D$16718=$A5)*('Raw Data'!$J$2:$J$16718=_xlfn.MAXIFS('Raw Data'!$J$2:$J$16718,'Raw Data'!$D$2:$D$16718,$A5))*ROW('Raw Data'!$D$2:$D$16718))),"N/A") -> Grand Theft Auto V
A6: Adventure | B6: =COUNTIF('Raw Data'!$D:$D,$A6) -> 1303 | C6: =SUMIF('Raw Data'!$D:$D,$A6,'Raw Data'!$J:$J) -> 237.69 | D6: =AVERAGEIFS('Raw Data'!$K:$K,'Raw Data'!$D:$D,$A6) -> 65.331269 | E6: =AVERAGEIFS('Raw Data'!$M:$M,'Raw Data'!$D:$D,$A6)*10 -> 71.33 | F6: =IFERROR(INDEX('Raw Data'!$A:$A,SUMPRODUCT(('Raw Data'!$D$2:$D$16718=$A6)*('Raw Data'!$J$2:$J$16718=_xlfn.MAXIFS('Raw Data'!$J$2:$J$16718,'Raw Data'!$D$2:$D$16718,$A6))*ROW('Raw Data'!$D$2:$D$16718))),"N/A") -> Super Mario Land 2: 6 Golden Coins | H6: Sum - Global_Sales | I6: Rating
A7: Fighting | B7: =COUNTIF('Raw Data'!$D:$D,$A7) -> 849 | C7: =SUMIF('Raw Data'!$D:$D,$A7,'Raw Data'!$J:$J) -> 447.48 | D7: =AVERAGEIFS('Raw Data'!$K:$K,'Raw Data'!$D:$D,$A7) -> 69.217604 | E7: =AVERAGEIFS('Raw Data'!$M:$M,'Raw Data'!$D:$D,$A7)*10 -> 73.025063 | F7: =IFERROR(INDEX('Raw Data'!$A:$A,SUMPRODUCT(('Raw Data'!$D$2:$D$16718=$A7)*('Raw Data'!$J$2:$J$16718=_xlfn.MAXIFS('Raw Data'!$J$2:$J$16718,'Raw Data'!$D$2:$D$16718,$A7))*ROW('Raw Data'!$D$2:$D$16718))),"N/A") -> Super Smash Bros. Brawl | H7: Genre | I7: AO | J7: E | K7: E10+ | L7: EC | M7: K-A | N7: M | O7: RP | P7: T | Q7: (empty) | R7: Total Result
A8: Misc | B8: =COUNTIF('Raw Data'!$D:$D,$A8) -> 1750 | C8: =SUMIF('Raw Data'!$D:$D,$A8,'Raw Data'!$J:$J) -> 803.18 | D8: =AVERAGEIFS('Raw Data'!$K:$K,'Raw Data'!$D:$D,$A8) -> 66.619503 | E8: =AVERAGEIFS('Raw Data'!$M:$M,'Raw Data'!$D:$D,$A8)*10 -> 68.193622 | F8: =IFERROR(INDEX('Raw Data'!$A:$A,SUMPRODUCT(('Raw Data'!$D$2:$D$16718=$A8)*('Raw Data'!$J$2:$J$16718=_xlfn.MAXIFS('Raw Data'!$J$2:$J$16718,'Raw Data'!$D$2:$D$16718,$A8))*ROW('Raw Data'!$D$2:$D$16718))),"N/A") -> Wii Play | H8: Action | I8: 1.95 | J8: 198.44 | K8: 219.04 | L8: 0.45 | N8: 601.82 | P8: 333.76 | Q8: 389.81 | R8: 1745.27
A9: Platform | B9: =COUNTIF('Raw Data'!$D:$D,$A9) -> 888 | C9: =SUMIF('Raw Data'!$D:$D,$A9,'Raw Data'!$J:$J) -> 828.08 | D9: =AVERAGEIFS('Raw Data'!$K:$K,'Raw Data'!$D:$D,$A9) -> 68.05835 | E9: =AVERAGEIFS('Raw Data'!$M:$M,'Raw Data'!$D:$D,$A9)*10 -> 73.014019 | F9: =IFERROR(INDEX('Raw Data'!$A:$A,SUMPRODUCT(('Raw Data'!$D$2:$D$16718=$A9)*('Raw Data'!$J$2:$J$16718=_xlfn.MAXIFS('Raw Data'!$J$2:$J$16718,'Raw Data'!$D$2:$D$16718,$A9))*ROW('Raw Data'!$D$2:$D$16718))),"N/A") -> Super Mario Bros. | H9: Adventure | J9: 58.01 | K9: 11.73 | L9: 0.36 | N9: 42.15 | P9: 19.34 | Q9: 106.1 | R9: 237.69
A10: Puzzle | B10: =COUNTIF('Raw Data'!$D:$D,$A10) -> 580 | C10: =SUMIF('Raw Data'!$D:$D,$A10,'Raw Data'!$J:$J) -> 243.02 | D10: =AVERAGEIFS('Raw Data'!$K:$K,'Raw Data'!$D:$D,$A10) -> 67.424107 | E10: =AVERAGEIFS('Raw Data'!$M:$M,'Raw Data'!$D:$D,$A10)*10 -> 71.75 | F10: =IFERROR(INDEX('Raw Data'!$A:$A,SUMPRODUCT(('Raw Data'!$D$2:$D$16718=$A10)*('Raw Data'!$J$2:$J$16718=_xlfn.MAXIFS('Raw Data'!$J$2:$J$16718,'Raw Data'!$D$2:$D$16718,$A10))*ROW('Raw Data'!$D$2:$D$16718))),"N/A") -> Tetris | H10: Fighting | J10: 1.09 | K10: 4.56 | N10: 28.8 | P10: 226.59 | Q10: 186.44 | R10: 447.48
A11: Racing | B11: =COUNTIF('Raw Data'!$D:$D,$A11) -> 1249 | C11: =SUMIF('Raw Data'!$D:$D,$A11,'Raw Data'!$J:$J) -> 728.9 | D11: =AVERAGEIFS('Raw Data'!$K:$K,'Raw Data'!$D:$D,$A11) -> 67.963612 | E11: =AVERAGEIFS('Raw Data'!$M:$M,'Raw Data'!$D:$D,$A11)*10 -> 70.361934 | F11: =IFERROR(INDEX('Raw Data'!$A:$A,SUMPRODUCT(('Raw Data'!$D$2:$D$16718=$A11)*('Raw Data'!$J$2:$J$16718=_xlfn.MAXIFS('Raw Data'!$J$2:$J$16718,'Raw Data'!$D$2:$D$16718,$A11))*ROW('Raw Data'!$D$2:$D$16718))),"N/A") -> Mario Kart Wii | H11: Misc | J11: 289.39 | K11: 115.13 | L11: 0.97 | M11: 1.92 | N11: 3.48 | P11: 129.78 | Q11: 262.51 | R11: 803.18
A12: Role-Playing | B12: =COUNTIF('Raw Data'!$D:$D,$A12) -> 1500 | C12: =SUMIF('Raw Data'!$D:$D,$A12,'Raw Data'!$J:$J) -> 934.4 | D12: =AVERAGEIFS('Raw Data'!$K:$K,'Raw Data'!$D:$D,$A12) -> 72.652646 | E12: =AVERAGEIFS('Raw Data'!$M:$M,'Raw Data'!$D:$D,$A12)*10 -> 76.195155 | F12: =IFERROR(INDEX('Raw Data'!$A:$A,SUMPRODUCT(('Raw Data'!$D$2:$D$16718=$A12)*('Raw Data'!$J$2:$J$16718=_xlfn.MAXIFS('Raw Data'!$J$2:$J$16718,'Raw Data'!$D$2:$D$16718,$A12))*ROW('Raw Data'!$D$2:$D$16718))),"N/A") -> Pokemon Red/Pokemon Blue | H12: Platform | J12: 329.8 | K12: 60.63 | N12: 1.6 | P12: 23.73 | Q12: 412.32 | R12: 828.08
A13: Shooter | B13: =COUNTIF('Raw Data'!$D:$D,$A13) -> 1323 | C13: =SUMIF('Raw Data'!$D:$D,$A13,'Raw Data'!$J:$J) -> 1052.94 | D13: =AVERAGEIFS('Raw Data'!$K:$K,'Raw Data'!$D:$D,$A13) -> 70.181144 | E13: =AVERAGEIFS('Raw Data'!$M:$M,'Raw Data'!$D:$D,$A13)*10 -> 70.418831 | F13: =IFERROR(INDEX('Raw Data'!$A:$A,SUMPRODUCT(('Raw Data'!$D$2:$D$16718=$A13)*('Raw Data'!$J$2:$J$16718=_xlfn.MAXIFS('Raw Data'!$J$2:$J$16718,'Raw Data'!$D$2:$D$16718,$A13))*ROW('Raw Data'!$D$2:$D$16718))),"N/A") -> Duck Hunt | H13: Puzzle | J13: 88.18 | K13: 22.33 | P13: 2.51 | Q13: 130 | R13: 243.02
A14: Simulation | B14: =COUNTIF('Raw Data'!$D:$D,$A14) -> 874 | C14: =SUMIF('Raw Data'!$D:$D,$A14,'Raw Data'!$J:$J) -> 390.42 | D14: =AVERAGEIFS('Raw Data'!$K:$K,'Raw Data'!$D:$D,$A14) -> 68.619318 | E14: =AVERAGEIFS('Raw Data'!$M:$M,'Raw Data'!$D:$D,$A14)*10 -> 71.34593 | F14: =IFERROR(INDEX('Raw Data'!$A:$A,SUMPRODUCT(('Raw Data'!$D$2:$D$16718=$A14)*('Raw Data'!$J$2:$J$16718=_xlfn.MAXIFS('Raw Data'!$J$2:$J$16718,'Raw Data'!$D$2:$D$16718,$A14))*ROW('Raw Data'!$D$2:$D$16718))),"N/A") -> Nintendogs | H14: Racing | J14: 369.74 | K14: 56.2 | N14: 4.97 | O14: 0.01 | P14: 96.53 | Q14: 201.45 | R14: 728.9
A15: Sports | B15: =COUNTIF('Raw Data'!$D:$D,$A15) -> 2348 | C15: =SUMIF('Raw Data'!$D:$D,$A15,'Raw Data'!$J:$J) -> 1332 | D15: =AVERAGEIFS('Raw Data'!$K:$K,'Raw Data'!$D:$D,$A15) -> 71.968174 | E15: =AVERAGEIFS('Raw Data'!$M:$M,'Raw Data'!$D:$D,$A15)*10 -> 69.611967 | F15: =IFERROR(INDEX('Raw Data'!$A:$A,SUMPRODUCT(('Raw Data'!$D$2:$D$16718=$A15)*('Raw Data'!$J$2:$J$16718=_xlfn.MAXIFS('Raw Data'!$J$2:$J$16718,'Raw Data'!$D$2:$D$16718,$A15))*ROW('Raw Data'!$D$2:$D$16718))),"N/A") -> Wii Sports | H15: Role-Playing | J15: 70.48 | K15: 50.48 | N15: 153.87 | P15: 239.49 | Q15: 420.08 | R15: 934.4
A16: Strategy | B16: =COUNTIF('Raw Data'!$D:$D,$A16) -> 683 | C16: =SUMIF('Raw Data'!$D:$D,$A16,'Raw Data'!$J:$J) -> 174.5 | D16: =AVERAGEIFS('Raw Data'!$K:$K,'Raw Data'!$D:$D,$A16) -> 72.086093 | E16: =AVERAGEIFS('Raw Data'!$M:$M,'Raw Data'!$D:$D,$A16)*10 -> 72.951768 | F16: =IFERROR(INDEX('Raw Data'!$A:$A,SUMPRODUCT(('Raw Data'!$D$2:$D$16718=$A16)*('Raw Data'!$J$2:$J$16718=_xlfn.MAXIFS('Raw Data'!$J$2:$J$16718,'Raw Data'!$D$2:$D$16718,$A16))*ROW('Raw Data'!$D$2:$D$16718))),"N/A") -> Pokemon Stadium | H16: Shooter | J16: 4.32 | K16: 20.84 | N16: 626.55 | P16: 200.47 | Q16: 200.76 | R16: 1052.94
H17: Simulation | J17: 160.74 | K17: 21.85 | N17: 1.32 | P17: 93.28 | Q17: 113.23 | R17: 390.42
H18: Sports | J18: 845.87 | K18: 53.66 | N18: 3.91 | P18: 94.86 | Q18: 333.7 | R18: 1332
H19: Strategy | J19: 20.84 | K19: 19.36 | M19: 2.41 | N19: 5.37 | O19: 0.07 | P19: 34.06 | Q19: 92.39 | R19: 174.5
H20: Total Result | I20: 1.95 | J20: 2436.9 | K20: 655.81 | L20: 1.78 | M20: 4.33 | N20: 1473.84 | O20: 0.08 | P20: 1494.4 | Q20: 2848.79 | R20: 8917.88

Sheet Sales Trends
A1: INDUSTRY SALES TRENDS
A2: Years with healthy sample sizes only (1996-2016); 2017+ rows are residual/incomplete.
A4: Year | B4: Releases | C4: Total Global Sales ($M) | D4: Avg Critic Score
A5: 1996 | B5: =COUNTIF('Raw Data'!$C:$C,$A5) -> 263 | C5: =SUMIF('Raw Data'!$C:$C,$A5,'Raw Data'!$J:$J) -> 199.15 | D5: =AVERAGEIFS('Raw Data'!$K:$K,'Raw Data'!$C:$C,$A5) -> 89.875
A6: 1997 | B6: =COUNTIF('Raw Data'!$C:$C,$A6) -> 289 | C6: =SUMIF('Raw Data'!$C:$C,$A6,'Raw Data'!$J:$J) -> 200.98 | D6: =AVERAGEIFS('Raw Data'!$K:$K,'Raw Data'!$C:$C,$A6) -> 85.294118
A7: 1998 | B7: =COUNTIF('Raw Data'!$C:$C,$A7) -> 379 | C7: =SUMIF('Raw Data'!$C:$C,$A7,'Raw Data'!$J:$J) -> 256.45 | D7: =AVERAGEIFS('Raw Data'!$K:$K,'Raw Data'!$C:$C,$A7) -> 81.821429
A8: 1999 | B8: =COUNTIF('Raw Data'!$C:$C,$A8) -> 338 | C8: =SUMIF('Raw Data'!$C:$C,$A8,'Raw Data'!$J:$J) -> 251.25 | D8: =AVERAGEIFS('Raw Data'!$K:$K,'Raw Data'!$C:$C,$A8) -> 75.769231
A9: 2000 | B9: =COUNTIF('Raw Data'!$C:$C,$A9) -> 350 | C9: =SUMIF('Raw Data'!$C:$C,$A9,'Raw Data'!$J:$J) -> 201.58 | D9: =AVERAGEIFS('Raw Data'!$K:$K,'Raw Data'!$C:$C,$A9) -> 69.34965
A10: 2001 | B10: =COUNTIF('Raw Data'!$C:$C,$A10) -> 482 | C10: =SUMIF('Raw Data'!$C:$C,$A10,'Raw Data'!$J:$J) -> 331.47 | D10: =AVERAGEIFS('Raw Data'!$K:$K,'Raw Data'!$C:$C,$A10) -> 71.41411
A11: 2002 | B11: =COUNTIF('Raw Data'!$C:$C,$A11) -> 829 | C11: =SUMIF('Raw Data'!$C:$C,$A11,'Raw Data'!$J:$J) -> 395.51 | D11: =AVERAGEIFS('Raw Data'!$K:$K,'Raw Data'!$C:$C,$A11) -> 69.046252
A12: 2003 | B12: =COUNTIF('Raw Data'!$C:$C,$A12) -> 775 | C12: =SUMIF('Raw Data'!$C:$C,$A12,'Raw Data'!$J:$J) -> 357.8 | D12: =AVERAGEIFS('Raw Data'!$K:$K,'Raw Data'!$C:$C,$A12) -> 70.181197
A13: 2004 | B13: =COUNTIF('Raw Data'!$C:$C,$A13) -> 762 | C13: =SUMIF('Raw Data'!$C:$C,$A13,'Raw Data'!$J:$J) -> 419.05 | D13: =AVERAGEIFS('Raw Data'!$K:$K,'Raw Data'!$C:$C,$A13) -> 69.393939
A14: 2005 | B14: =COUNTIF('Raw Data'!$C:$C,$A14) -> 939 | C14: =SUMIF('Raw Data'!$C:$C,$A14,'Raw Data'!$J:$J) -> 458.31 | D14: =AVERAGEIFS('Raw Data'!$K:$K,'Raw Data'!$C:$C,$A14) -> 68.819847
A15: 2006 | B15: =COUNTIF('Raw Data'!$C:$C,$A15) -> 1006 | C15: =SUMIF('Raw Data'!$C:$C,$A15,'Raw Data'!$J:$J) -> 518.22 | D15: =AVERAGEIFS('Raw Data'!$K:$K,'Raw Data'!$C:$C,$A15) -> 67.33871
A16: 2007 | B16: =COUNTIF('Raw Data'!$C:$C,$A16) -> 1197 | C16: =SUMIF('Raw Data'!$C:$C,$A16,'Raw Data'!$J:$J) -> 605.37 | D16: =AVERAGEIFS('Raw Data'!$K:$K,'Raw Data'!$C:$C,$A16) -> 66.180636
... A25: 2016 | B25: =COUNTIF('Raw Data'!$C:$C,$A25) -> 502 | C25: =SUMIF('Raw Data'!$C:$C,$A25,'Raw Data'!$J:$J) -> 130.1 | D25: =AVERAGEIFS('Raw Data'!$K:$K,'Raw Data'!$C:$C,$A25) -> 73.155172
A27: Top Publishers by Total Global Sales
A28: Publisher | B28: Games | C28: Total Global Sales ($M) | D28: Avg Sales / Game
A29: Nintendo | B29: =COUNTIF('Raw Data'!$E:$E,$A29) -> 706 | C29: =SUMIF('Raw Data'!$E:$E,$A29,'Raw Data'!$J:$J) -> 1788.81 | D29: =IF(B29=0,0,C29/B29) -> 2.5337252
A30: Electronic Arts | B30: =COUNTIF('Raw Data'!$E:$E,$A30) -> 1356 | C30: =SUMIF('Raw Data'!$E:$E,$A30,'Raw Data'!$J:$J) -> 1116.96 | D30: =IF(B30=0,0,C30/B30) -> 0.82371681
A31: Activision | B31: =COUNTIF('Raw Data'!$E:$E,$A31) -> 985 | C31: =SUMIF('Raw Data'!$E:$E,$A31,'Raw Data'!$J:$J) -> 731.16 | D31: =IF(B31=0,0,C31/B31) -> 0.74229442
A32: Sony Computer Entertainment | B32: =COUNTIF('Raw Data'!$E:$E,$A32) -> 687 | C32: =SUMIF('Raw Data'!$E:$E,$A32,'Raw Data'!$J:$J) -> 606.48 | D32: =IF(B32=0,0,C32/B32) -> 0.88279476
A33: Ubisoft | B33: =COUNTIF('Raw Data'!$E:$E,$A33) -> 933 | C33: =SUMIF('Raw Data'!$E:$E,$A33,'Raw Data'!$J:$J) -> 471.61 | D33: =IF(B33=0,0,C33/B33) -> 0.50547696
A34: Take-Two Interactive | B34: =COUNTIF('Raw Data'!$E:$E,$A34) -> 422 | C34: =SUMIF('Raw Data'!$E:$E,$A34,'Raw Data'!$J:$J) -> 403.82 | D34: =IF(B34=0,0,C34/B34) -> 0.95691943
A35: THQ | B35: =COUNTIF('Raw Data'!$E:$E,$A35) -> 715 | C35: =SUMIF('Raw Data'!$E:$E,$A35,'Raw Data'!$J:$J) -> 338.44 | D35: =IF(B35=0,0,C35/B35) -> 0.47334266
A36: Konami Digital Entertainment | B36: =COUNTIF('Raw Data'!$E:$E,$A36) -> 834 | C36: =SUMIF('Raw Data'!$E:$E,$A36,'Raw Data'!$J:$J) -> 282.39 | D36: =IF(B36=0,0,C36/B36) -> 0.33859712
A37: Sega | B37: =COUNTIF('Raw Data'!$E:$E,$A37) -> 638 | C37: =SUMIF('Raw Data'!$E:$E,$A37,'Raw Data'!$J:$J) -> 270.35 | D37: =IF(B37=0,0,C37/B37) -> 0.42374608
A38: Namco Bandai Games | B38: =COUNTIF('Raw Data'!$E:$E,$A38) -> 939 | C38: =SUMIF('Raw Data'!$E:$E,$A38,'Raw Data'!$J:$J) -> 254.62 | D38: =IF(B38=0,0,C38/B38) -> 0.27116081
