Workbook

Sheet README
A1: NBA Player Stat Projections -- Portfolio Project
A2: Data analyst portfolio piece | Built in Excel (openpyxl + native pivot tables)
A4: Data Source
A5: "NBA Players stats since 1950" -- Kaggle dataset by drgilermo. https://www.kaggle.com/datasets/drgilermo/nba-players-stats
A6: Filtered to the 2008-2017 seasons (10 most recent complete seasons at time of original scrape) and deduplicated so traded players show one combined "TOT" row per season instead of one row per team. 4,669 player-season rows, 29 original columns retained.
A8: Why this dataset
A9: Real box-score and advanced-metric data (PER, TS%, Win Shares) at the player-season grain is clean enough for reliable formulas but rich enough to need genuine lookup, ranking, and projection logic -- a good fit for demonstrating intermediate Excel skills without forcing them.
A11: Technique Map
A12: Technique / Function | B12: Sheet | C12: Cell(s) | D12: Purpose
A13: LEFT + FIND + IFERROR | B13: Raw Data | C13: AE2 (col AE) | D13: Extracts primary position from combo listings like "SG-PF".
A14: Text concatenation (&) | B14: Raw Data | C14: AF2 (col AF) | D14: Builds a unique Player|Season composite key for lookups.
A15: SUMPRODUCT (conditional rank) | B15: Raw Data | C15: AG2 (col AG) | D15: Ranks each player's PTS within their own season; works around RANK()'s single-criterion limit.
A16: INDEX/MATCH (key cell) | B16: Player Lookup | C16: C9:C25 | D16: Pulls a full stat line for one typed Player + Season.
A17: INDEX/MATCH (inline key) | B17: Season Rankings | C17: C15:E19 | D17: Compares 5 featured players for whichever season is selected.
A18: COUNTIF | B18: Season Rankings | C18: D6 | D18: Counts players active in the selected season.
A19: AVERAGEIFS | B19: Season Rankings | C19: D7:D8 | D19: League-wide averages for the selected season.
A20: COUNTIFS | B20: Season Rankings | C20: D9 | D20: Two-condition count (season + PPG threshold).
A21: SUMIF | B21: Season Rankings | C21: D10 | D21: Single-condition sum of league points.
A22: MAXIFS | B22: Season Rankings | C22: D11 | D22: Highest scorer for the selected season.
A23: Conditional formatting (color scale + data bar) | B23: Season Rankings | C23: C15:D19 | D23: Visually flags best ranks and highest point totals.
... A29: Line Chart | B29: Player Projections | C29: below table | D29: Plots actual PPG trend plus the 2018 projection point.
A32: Tip: click any formula cell across this workbook -- cells with a small red corner marker have a comment explaining the technique used, in addition to this map.

Sheet Raw Data
A1: Season | B1: Player | C1: Pos | D1: Age | E1: Tm | F1: G | G1: GS | H1: MP | I1: FG | J1: FGA | K1: FG% | L1: 3P | M1: 3PA | N1: 3P% | O1: FT | P1: FTA | Q1: FT% | R1: ORB | S1: DRB | T1: TRB | U1: AST | V1: STL | W1: BLK | X1: TOV | Y1: PF | Z1: PTS | AA1: PER | AB1: TS% | AC1: WS | AD1: PPG | AE1: PrimaryPos | AF1: PlayerSeasonKey | AG1: SeasonRankPTS
A2: 2008 | B2: Aaron Brooks | C2: PG | D2: 23 | E2: HOU | F2: 51 | G2: 0 | H2: 608 | I2: 93 | J2: 225 | K2: 0.413 | L2: 36 | M2: 109 | N2: 0.33 | O2: 42 | P2: 49 | Q2: 0.857 | R2: 13 | S2: 43 | T2: 56 | U2: 87 | V2: 13 | W2: 5 | X2: 44 | Y2: 69 | Z2: 264 | AA2: 13.1 | AB2: 0.535 | AC2: 1.4 | AD2: =IF(F2=0,0,Z2/F2) -> 5.1764706 | AE2: =IFERROR(LEFT(C2,FIND("-",C2)-1),C2) -> PG | AF2: =B2&"|"&A2 -> Aaron Brooks|2008 | AG2: =SUMPRODUCT(($A$2:$A$4670=A2)*($Z$2:$Z$4670>Z2))+1 -> 272
A3: 2008 | B3: Aaron Gray | C3: C | D3: 23 | E3: CHI | F3: 61 | G3: 1 | H3: 613 | I3: 103 | J3: 204 | K3: 0.505 | L3: 0 | M3: 1 | N3: 0 | O3: 56 | P3: 99 | Q3: 0.566 | R3: 70 | S3: 98 | T3: 168 | U3: 41 | V3: 21 | W3: 16 | X3: 57 | Y3: 117 | Z3: 262 | AA3: 13.9 | AB3: 0.529 | AC3: 0.8 | AD3: =IF(F3=0,0,Z3/F3) -> 4.295082 | AE3: =IFERROR(LEFT(C3,FIND("-",C3)-1),C3) -> C | AF3: =B3&"|"&A3 -> Aaron Gray|2008 | AG3: =SUMPRODUCT(($A$2:$A$4670=A3)*($Z$2:$Z$4670>Z3))+1 -> 274
A4: 2008 | B4: Aaron Williams | C4: C | D4: 36 | E4: LAC | F4: 30 | G4: 5 | H4: 297 | I4: 27 | J4: 55 | K4: 0.491 | L4: 0 | M4: 0 | O4: 14 | P4: 18 | Q4: 0.778 | R4: 15 | S4: 46 | T4: 61 | U4: 9 | V4: 12 | W4: 15 | X4: 13 | Y4: 44 | Z4: 68 | AA4: 10.3 | AB4: 0.54 | AC4: 0.4 | AD4: =IF(F4=0,0,Z4/F4) -> 2.2666667 | AE4: =IFERROR(LEFT(C4,FIND("-",C4)-1),C4) -> C | AF4: =B4&"|"&A4 -> Aaron Williams|2008 | AG4: =SUMPRODUCT(($A$2:$A$4670=A4)*($Z$2:$Z$4670>Z4))+1 -> 370
A5: 2008 | B5: Acie Law | C5: PG | D5: 23 | E5: ATL | F5: 56 | G5: 6 | H5: 865 | I5: 95 | J5: 237 | K5: 0.401 | L5: 7 | M5: 34 | N5: 0.206 | O5: 38 | P5: 48 | Q5: 0.792 | R5: 12 | S5: 45 | T5: 57 | U5: 113 | V5: 29 | W5: 0 | X5: 56 | Y5: 73 | Z5: 235 | AA5: 7.7 | AB5: 0.455 | AC5: -0.1 | AD5: =IF(F5=0,0,Z5/F5) -> 4.1964286 | AE5: =IFERROR(LEFT(C5,FIND("-",C5)-1),C5) -> PG | AF5: =B5&"|"&A5 -> Acie Law|2008 | AG5: =SUMPRODUCT(($A$2:$A$4670=A5)*($Z$2:$Z$4670>Z5))+1 -> 284
A6: 2008 | B6: Adonal Foyle | C6: C | D6: 32 | E6: ORL | F6: 82 | G6: 0 | H6: 774 | I6: 70 | J6: 153 | K6: 0.458 | L6: 0 | M6: 0 | O6: 16 | P6: 34 | Q6: 0.471 | R6: 71 | S6: 137 | T6: 208 | U6: 18 | V6: 16 | W6: 45 | X6: 32 | Y6: 94 | Z6: 156 | AA6: 9.9 | AB6: 0.464 | AC6: 1.3 | AD6: =IF(F6=0,0,Z6/F6) -> 1.902439 | AE6: =IFERROR(LEFT(C6,FIND("-",C6)-1),C6) -> C | AF6: =B6&"|"&A6 -> Adonal Foyle|2008 | AG6: =SUMPRODUCT(($A$2:$A$4670=A6)*($Z$2:$Z$4670>Z6))+1 -> 314
A7: 2008 | B7: Adrian Griffin | C7: SG-SF | D7: 33 | E7: TOT | F7: 35 | G7: 2 | H7: 307 | I7: 30 | J7: 76 | K7: 0.395 | L7: 0 | M7: 0 | O7: 5 | P7: 9 | Q7: 0.556 | R7: 28 | S7: 31 | T7: 59 | U7: 27 | V7: 17 | W7: 2 | X7: 21 | Y7: 27 | Z7: 65 | AA7: 8.7 | AB7: 0.406 | AC7: 0 | AD7: =IF(F7=0,0,Z7/F7) -> 1.8571429 | AE7: =IFERROR(LEFT(C7,FIND("-",C7)-1),C7) -> SG | AF7: =B7&"|"&A7 -> Adrian Griffin|2008 | AG7: =SUMPRODUCT(($A$2:$A$4670=A7)*($Z$2:$Z$4670>Z7))+1 -> 372
A8: 2008 | B8: Al Harrington | C8: C | D8: 27 | E8: GSW | F8: 81 | G8: 59 | H8: 2190 | I8: 401 | J8: 923 | K8: 0.434 | L8: 153 | M8: 408 | N8: 0.375 | O8: 147 | P8: 190 | Q8: 0.774 | R8: 107 | S8: 332 | T8: 439 | U8: 132 | V8: 74 | W8: 16 | X8: 90 | Y8: 266 | Z8: 1102 | AA8: 15.6 | AB8: 0.547 | AC8: 5.4 | AD8: =IF(F8=0,0,Z8/F8) -> 13.604938 | AE8: =IFERROR(LEFT(C8,FIND("-",C8)-1),C8) -> C | AF8: =B8&"|"&A8 -> Al Harrington|2008 | AG8: =SUMPRODUCT(($A$2:$A$4670=A8)*($Z$2:$Z$4670>Z8))+1 -> 67
A9: 2008 | B9: Al Horford | C9: C | D9: 21 | E9: ATL | F9: 81 | G9: 77 | H9: 2540 | I9: 333 | J9: 668 | K9: 0.499 | L9: 0 | M9: 5 | N9: 0 | O9: 155 | P9: 212 | Q9: 0.731 | R9: 248 | S9: 537 | T9: 785 | U9: 124 | V9: 60 | W9: 76 | X9: 137 | Y9: 267 | Z9: 821 | AA9: 14.7 | AB9: 0.539 | AC9: 5.5 | AD9: =IF(F9=0,0,Z9/F9) -> 10.135802 | AE9: =IFERROR(LEFT(C9,FIND("-",C9)-1),C9) -> C | AF9: =B9&"|"&A9 -> Al Horford|2008 | AG9: =SUMPRODUCT(($A$2:$A$4670=A9)*($Z$2:$Z$4670>Z9))+1 -> 120
A10: 2008 | B10: Al Jefferson | C10: C | D10: 23 | E10: MIN | F10: 82 | G10: 82 | H10: 2919 | I10: 721 | J10: 1441 | K10: 0.5 | L10: 0 | M10: 5 | N10: 0 | O10: 284 | P10: 394 | Q10: 0.721 | R10: 308 | S10: 603 | T10: 911 | U10: 117 | V10: 74 | W10: 119 | X10: 167 | Y10: 222 | Z10: 1726 | AA10: 22.7 | AB10: 0.535 | AC10: 7.7 | AD10: =IF(F10=0,0,Z10/F10) -> 21.04878 | AE10: =IFERROR(LEFT(C10,FIND("-",C10)-1),C10) -> C | AF10: =B10&"|"&A10 -> Al Jefferson|2008 | AG10: =SUMPRODUCT(($A$2:$A$4670=A10)*($Z$2:$Z$4670>Z10))+1 -> 11
A11: 2008 | B11: Al Thornton | C11: PF | D11: 24 | E11: LAC | F11: 79 | G11: 31 | H11: 2158 | I11: 374 | J11: 871 | K11: 0.429 | L11: 43 | M11: 130 | N11: 0.331 | O11: 214 | P11: 288 | Q11: 0.743 | R11: 98 | S11: 260 | T11: 358 | U11: 98 | V11: 46 | W11: 43 | X11: 128 | Y11: 195 | Z11: 1005 | AA11: 12.7 | AB11: 0.504 | AC11: 1.1 | AD11: =IF(F11=0,0,Z11/F11) -> 12.721519 | AE11: =IFERROR(LEFT(C11,FIND("-",C11)-1),C11) -> PF | AF11: =B11&"|"&A11 -> Al Thornton|2008 | AG11: =SUMPRODUCT(($A$2:$A$4670=A11)*($Z$2:$Z$4670>Z11))+1 -> 78
A12: 2008 | B12: Alando Tucker | C12: SF | D12: 23 | E12: PHO | F12: 6 | G12: 0 | H12: 48 | I12: 8 | J12: 22 | K12: 0.364 | L12: 1 | M12: 4 | N12: 0.25 | O12: 5 | P12: 6 | Q12: 0.833 | R12: 4 | S12: 4 | T12: 8 | U12: 0 | V12: 0 | W12: 1 | X12: 0 | Y12: 2 | Z12: 22 | AA12: 11.8 | AB12: 0.446 | AC12: 0 | AD12: =IF(F12=0,0,Z12/F12) -> 3.6666667 | AE12: =IFERROR(LEFT(C12,FIND("-",C12)-1),C12) -> SF | AF12: =B12&"|"&A12 -> Alando Tucker|2008 | AG12: =SUMPRODUCT(($A$2:$A$4670=A12)*($Z$2:$Z$4670>Z12))+1 -> 414
A13: 2008 | B13: Alexander Johnson | C13: PF | D13: 24 | E13: MIA | F13: 43 | G13: 6 | H13: 549 | I13: 61 | J13: 125 | K13: 0.488 | L13: 0 | M13: 0 | O13: 57 | P13: 83 | Q13: 0.687 | R13: 32 | S13: 62 | T13: 94 | U13: 13 | V13: 13 | W13: 10 | X13: 42 | Y13: 80 | Z13: 179 | AA13: 8.9 | AB13: 0.554 | AC13: 0.2 | AD13: =IF(F13=0,0,Z13/F13) -> 4.1627907 | AE13: =IFERROR(LEFT(C13,FIND("-",C13)-1),C13) -> PF | AF13: =B13&"|"&A13 -> Alexander Johnson|2008 | AG13: =SUMPRODUCT(($A$2:$A$4670=A13)*($Z$2:$Z$4670>Z13))+1 -> 303
A14: 2008 | B14: Allen Iverson* | C14: SG | D14: 32 | E14: DEN | F14: 82 | G14: 82 | H14: 3424 | I14: 712 | J14: 1556 | K14: 0.458 | L14: 95 | M14: 275 | N14: 0.345 | O14: 645 | P14: 797 | Q14: 0.809 | R14: 47 | S14: 196 | T14: 243 | U14: 586 | V14: 160 | W14: 12 | X14: 245 | Y14: 109 | Z14: 2164 | AA14: 20.9 | AB14: 0.567 | AC14: 11.6 | AD14: =IF(F14=0,0,Z14/F14) -> 26.390244 | AE14: =IFERROR(LEFT(C14,FIND("-",C14)-1),C14) -> SG | AF14: =B14&"|"&A14 -> Allen Iverson*|2008 | AG14: =SUMPRODUCT(($A$2:$A$4670=A14)*($Z$2:$Z$4670>Z14))+1 -> 3
A15: 2008 | B15: Alonzo Mourning* | C15: C | D15: 37 | E15: MIA | F15: 25 | G15: 0 | H15: 389 | I15: 52 | J15: 95 | K15: 0.547 | L15: 0 | M15: 0 | O15: 45 | P15: 76 | Q15: 0.592 | R15: 34 | S15: 59 | T15: 93 | U15: 7 | V15: 4 | W15: 42 | X15: 25 | Y15: 56 | Z15: 149 | AA15: 16.2 | AB15: 0.58 | AC15: 0.8 | AD15: =IF(F15=0,0,Z15/F15) -> 5.96 | AE15: =IFERROR(LEFT(C15,FIND("-",C15)-1),C15) -> C | AF15: =B15&"|"&A15 -> Alonzo Mourning*|2008 | AG15: =SUMPRODUCT(($A$2:$A$4670=A15)*($Z$2:$Z$4670>Z15))+1 -> 319
A16: 2008 | B16: Amar'e Stoudemire | C16: C | D16: 25 | E16: PHO | F16: 79 | G16: 79 | H16: 2677 | I16: 714 | J16: 1211 | K16: 0.59 | L16: 5 | M16: 31 | N16: 0.161 | O16: 556 | P16: 691 | Q16: 0.805 | R16: 178 | S16: 541 | T16: 719 | U16: 118 | V16: 64 | W16: 163 | X16: 174 | Y16: 294 | Z16: 1989 | AA16: 27.6 | AB16: 0.656 | AC16: 14.6 | AD16: =IF(F16=0,0,Z16/F16) -> 25.177215 | AE16: =IFERROR(LEFT(C16,FIND("-",C16)-1),C16) -> C | AF16: =B16&"|"&A16 -> Amar'e Stoudemire|2008 | AG16: =SUMPRODUCT(($A$2:$A$4670=A16)*($Z$2:$Z$4670>Z16))+1 -> 4
A17: 2008 | B17: Amir Johnson | C17: PF | D17: 20 | E17: DET | F17: 62 | G17: 0 | H17: 764 | I17: 92 | J17: 165 | K17: 0.558 | L17: 0 | M17: 0 | O17: 37 | P17: 55 | Q17: 0.673 | R17: 87 | S17: 148 | T17: 235 | U17: 29 | V17: 24 | W17: 82 | X17: 39 | Y17: 141 | Z17: 221 | AA17: 17.5 | AB17: 0.584 | AC17: 3 | AD17: =IF(F17=0,0,Z17/F17) -> 3.5645161 | AE17: =IFERROR(LEFT(C17,FIND("-",C17)-1),C17) -> PF | AF17: =B17&"|"&A17 -> Amir Johnson|2008 | AG17: =SUMPRODUCT(($A$2:$A$4670=A17)*($Z$2:$Z$4670>Z17))+1 -> 290
A18: 2008 | B18: Anderson Varejao | C18: C | D18: 25 | E18: CLE | F18: 48 | G18: 13 | H18: 1320 | I18: 136 | J18: 295 | K18: 0.461 | L18: 0 | M18: 2 | N18: 0 | O18: 49 | P18: 82 | Q18: 0.598 | R18: 134 | S18: 265 | T18: 399 | U18: 53 | V18: 37 | W18: 26 | X18: 59 | Y18: 134 | Z18: 321 | AA18: 12 | AB18: 0.485 | AC18: 2.4 | AD18: =IF(F18=0,0,Z18/F18) -> 6.6875 | AE18: =IFERROR(LEFT(C18,FIND("-",C18)-1),C18) -> C | AF18: =B18&"|"&A18 -> Anderson Varejao|2008 | AG18: =SUMPRODUCT(($A$2:$A$4670=A18)*($Z$2:$Z$4670>Z18))+1 -> 260
A19: 2008 | B19: Andray Blatche | C19: PF | D19: 21 | E19: WAS | F19: 82 | G19: 15 | H19: 1675 | I19: 254 | J19: 536 | K19: 0.474 | L19: 3 | M19: 13 | N19: 0.231 | O19: 107 | P19: 154 | Q19: 0.695 | R19: 164 | S19: 261 | T19: 425 | U19: 92 | V19: 53 | W19: 114 | X19: 112 | Y19: 258 | Z19: 618 | AA19: 15.5 | AB19: 0.512 | AC19: 3 | AD19: =IF(F19=0,0,Z19/F19) -> 7.5365854 | AE19: =IFERROR(LEFT(C19,FIND("-",C19)-1),C19) -> PF | AF19: =B19&"|"&A19 -> Andray Blatche|2008 | AG19: =SUMPRODUCT(($A$2:$A$4670=A19)*($Z$2:$Z$4670>Z19))+1 -> 161
A20: 2008 | B20: Andre Barrett | C20: PG | D20: 25 | E20: LAC | F20: 4 | G20: 0 | H20: 25 | I20: 2 | J20: 5 | K20: 0.4 | L20: 1 | M20: 3 | N20: 0.333 | O20: 1 | P20: 2 | Q20: 0.5 | R20: 0 | S20: 1 | T20: 1 | U20: 7 | V20: 0 | W20: 0 | X20: 1 | Y20: 1 | Z20: 6 | AA20: 12.5 | AB20: 0.51 | AC20: 0 | AD20: =IF(F20=0,0,Z20/F20) -> 1.5 | AE20: =IFERROR(LEFT(C20,FIND("-",C20)-1),C20) -> PG | AF20: =B20&"|"&A20 -> Andre Barrett|2008 | AG20: =SUMPRODUCT(($A$2:$A$4670=A20)*($Z$2:$Z$4670>Z20))+1 -> 438
A21: 2008 | B21: Andre Brown | C21: PF | D21: 26 | E21: MEM | F21: 33 | G21: 1 | H21: 286 | I21: 39 | J21: 78 | K21: 0.5 | L21: 0 | M21: 0 | O21: 22 | P21: 49 | Q21: 0.449 | R21: 37 | S21: 55 | T21: 92 | U21: 8 | V21: 7 | W21: 4 | X21: 14 | Y21: 38 | Z21: 100 | AA21: 13.5 | AB21: 0.502 | AC21: 0.4 | AD21: =IF(F21=0,0,Z21/F21) -> 3.030303 | AE21: =IFERROR(LEFT(C21,FIND("-",C21)-1),C21) -> PF | AF21: =B21&"|"&A21 -> Andre Brown|2008 | AG21: =SUMPRODUCT(($A$2:$A$4670=A21)*($Z$2:$Z$4670>Z21))+1 -> 348
A22: 2008 | B22: Andre Iguodala | C22: SF | D22: 24 | E22: PHI | F22: 82 | G22: 82 | H22: 3242 | I22: 582 | J22: 1277 | K22: 0.456 | L22: 101 | M22: 307 | N22: 0.329 | O22: 365 | P22: 506 | Q22: 0.721 | R22: 85 | S22: 361 | T22: 446 | U22: 391 | V22: 171 | W22: 49 | X22: 214 | Y22: 187 | Z22: 1630 | AA22: 19 | AB22: 0.543 | AC22: 9.6 | AD22: =IF(F22=0,0,Z22/F22) -> 19.878049 | AE22: =IFERROR(LEFT(C22,FIND("-",C22)-1),C22) -> SF | AF22: =B22&"|"&A22 -> Andre Iguodala|2008 | AG22: =SUMPRODUCT(($A$2:$A$4670=A22)*($Z$2:$Z$4670>Z22))+1 -> 20
A23: 2008 | B23: Andre Miller | C23: PG | D23: 31 | E23: PHI | F23: 82 | G23: 82 | H23: 3016 | I23: 569 | J23: 1156 | K23: 0.492 | L23: 3 | M23: 34 | N23: 0.088 | O23: 257 | P23: 333 | Q23: 0.772 | R23: 95 | S23: 229 | T23: 324 | U23: 565 | V23: 105 | W23: 6 | X23: 206 | Y23: 181 | Z23: 1398 | AA23: 18.4 | AB23: 0.537 | AC23: 8.3 | AD23: =IF(F23=0,0,Z23/F23) -> 17.04878 | AE23: =IFERROR(LEFT(C23,FIND("-",C23)-1),C23) -> PG | AF23: =B23&"|"&A23 -> Andre Miller|2008 | AG23: =SUMPRODUCT(($A$2:$A$4670=A23)*($Z$2:$Z$4670>Z23))+1 -> 39
A24: 2008 | B24: Andre Owens | C24: PG | D24: 27 | E24: IND | F24: 31 | G24: 7 | H24: 392 | I24: 40 | J24: 107 | K24: 0.374 | L24: 18 | M24: 40 | N24: 0.45 | O24: 25 | P24: 34 | Q24: 0.735 | R24: 13 | S24: 34 | T24: 47 | U24: 47 | V24: 13 | W24: 3 | X24: 24 | Y24: 37 | Z24: 123 | AA24: 10 | AB24: 0.504 | AC24: 0.4 | AD24: =IF(F24=0,0,Z24/F24) -> 3.9677419 | AE24: =IFERROR(LEFT(C24,FIND("-",C24)-1),C24) -> PG | AF24: =B24&"|"&A24 -> Andre Owens|2008 | AG24: =SUMPRODUCT(($A$2:$A$4670=A24)*($Z$2:$Z$4670>Z24))+1 -> 332
A25: 2008 | B25: Andrea Bargnani | C25: PF | D25: 22 | E25: TOR | F25: 78 | G25: 53 | H25: 1861 | I25: 280 | J25: 725 | K25: 0.386 | L25: 90 | M25: 261 | N25: 0.345 | O25: 142 | P25: 169 | Q25: 0.84 | R25: 50 | S25: 238 | T25: 288 | U25: 89 | V25: 23 | W25: 37 | X25: 88 | Y25: 211 | Z25: 792 | AA25: 10.6 | AB25: 0.495 | AC25: 1.4 | AD25: =IF(F25=0,0,Z25/F25) -> 10.153846 | AE25: =IFERROR(LEFT(C25,FIND("-",C25)-1),C25) -> PF | AF25: =B25&"|"&A25 -> Andrea Bargnani|2008 | AG25: =SUMPRODUCT(($A$2:$A$4670=A25)*($Z$2:$Z$4670>Z25))+1 -> 125
A26: 2008 | B26: Andrei Kirilenko | C26: SF | D26: 26 | E26: UTA | F26: 72 | G26: 72 | H26: 2217 | I26: 275 | J26: 544 | K26: 0.506 | L26: 44 | M26: 116 | N26: 0.379 | O26: 198 | P26: 257 | Q26: 0.77 | R26: 121 | S26: 218 | T26: 339 | U26: 285 | V26: 86 | W26: 109 | X26: 140 | Y26: 165 | Z26: 792 | AA26: 17.2 | AB26: 0.603 | AC26: 7.1 | AD26: =IF(F26=0,0,Z26/F26) -> 11 | AE26: =IFERROR(LEFT(C26,FIND("-",C26)-1),C26) -> SF | AF26: =B26&"|"&A26 -> Andrei Kirilenko|2008 | AG26: =SUMPRODUCT(($A$2:$A$4670=A26)*($Z$2:$Z$4670>Z26))+1 -> 125
A27: 2008 | B27: Andres Nocioni | C27: SF | D27: 28 | E27: CHI | F27: 82 | G27: 27 | H27: 2021 | I27: 379 | J27: 877 | K27: 0.432 | L27: 126 | M27: 346 | N27: 0.364 | O27: 196 | P27: 243 | Q27: 0.807 | R27: 48 | S27: 294 | T27: 342 | U27: 95 | V27: 25 | W27: 43 | X27: 133 | Y27: 245 | Z27: 1080 | AA27: 13.6 | AB27: 0.549 | AC27: 3.3 | AD27: =IF(F27=0,0,Z27/F27) -> 13.170732 | AE27: =IFERROR(LEFT(C27,FIND("-",C27)-1),C27) -> SF | AF27: =B27&"|"&A27 -> Andres Nocioni|2008 | AG27: =SUMPRODUCT(($A$2:$A$4670=A27)*($Z$2:$Z$4670>Z27))+1 -> 70
A28: 2008 | B28: Andrew Bogut | C28: C | D28: 23 | E28: MIL | F28: 78 | G28: 78 | H28: 2720 | I28: 465 | J28: 910 | K28: 0.511 | L28: 0 | M28: 7 | N28: 0 | O28: 189 | P28: 322 | Q28: 0.587 | R28: 245 | S28: 518 | T28: 763 | U28: 199 | V28: 64 | W28: 135 | X28: 172 | Y28: 254 | Z28: 1119 | AA28: 17.5 | AB28: 0.532 | AC28: 4.8 | AD28: =IF(F28=0,0,Z28/F28) -> 14.346154 | AE28: =IFERROR(LEFT(C28,FIND("-",C28)-1),C28) -> C | AF28: =B28&"|"&A28 -> Andrew Bogut|2008 | AG28: =SUMPRODUCT(($A$2:$A$4670=A28)*($Z$2:$Z$4670>Z28))+1 -> 65
A29: 2008 | B29: Andrew Bynum | C29: C | D29: 20 | E29: LAL | F29: 35 | G29: 25 | H29: 1008 | I29: 189 | J29: 297 | K29: 0.636 | L29: 0 | M29: 0 | O29: 82 | P29: 118 | Q29: 0.695 | R29: 105 | S29: 251 | T29: 356 | U29: 61 | V29: 12 | W29: 72 | X29: 52 | Y29: 98 | Z29: 460 | AA29: 22.6 | AB29: 0.659 | AC29: 4.8 | AD29: =IF(F29=0,0,Z29/F29) -> 13.142857 | AE29: =IFERROR(LEFT(C29,FIND("-",C29)-1),C29) -> C | AF29: =B29&"|"&A29 -> Andrew Bynum|2008 | AG29: =SUMPRODUCT(($A$2:$A$4670=A29)*($Z$2:$Z$4670>Z29))+1 -> 217
A30: 2008 | B30: Andris Biedrins | C30: C | D30: 21 | E30: GSW | F30: 76 | G30: 59 | H30: 2078 | I30: 340 | J30: 543 | K30: 0.626 | L30: 0 | M30: 0 | O30: 116 | P30: 187 | Q30: 0.62 | R30: 256 | S30: 488 | T30: 744 | U30: 75 | V30: 56 | W30: 94 | X30: 85 | Y30: 262 | Z30: 796 | AA30: 19.2 | AB30: 0.637 | AC30: 8 | AD30: =IF(F30=0,0,Z30/F30) -> 10.473684 | AE30: =IFERROR(LEFT(C30,FIND("-",C30)-1),C30) -> C | AF30: =B30&"|"&A30 -> Andris Biedrins|2008 | AG30: =SUMPRODUCT(($A$2:$A$4670=A30)*($Z$2:$Z$4670>Z30))+1 -> 124
A31: 2008 | B31: Anfernee Hardaway | C31: SF | D31: 36 | E31: MIA | F31: 16 | G31: 8 | H31: 325 | I31: 22 | J31: 60 | K31: 0.367 | L31: 8 | M31: 19 | N31: 0.421 | O31: 8 | P31: 9 | Q31: 0.889 | R31: 3 | S31: 32 | T31: 35 | U31: 35 | V31: 19 | W31: 1 | X31: 13 | Y31: 24 | Z31: 60 | AA31: 9 | AB31: 0.469 | AC31: 0.2 | AD31: =IF(F31=0,0,Z31/F31) -> 3.75 | AE31: =IFERROR(LEFT(C31,FIND("-",C31)-1),C31) -> SF | AF31: =B31&"|"&A31 -> Anfernee Hardaway|2008 | AG31: =SUMPRODUCT(($A$2:$A$4670=A31)*($Z$2:$Z$4670>Z31))+1 -> 375
A32: 2008 | B32: Antawn Jamison | C32: PF | D32: 31 | E32: WAS | F32: 79 | G32: 79 | H32: 3061 | I32: 618 | J32: 1417 | K32: 0.436 | L32: 120 | M32: 354 | N32: 0.339 | O32: 333 | P32: 438 | Q32: 0.76 | R32: 215 | S32: 591 | T32: 806 | U32: 120 | V32: 106 | W32: 34 | X32: 113 | Y32: 195 | Z32: 1689 | AA32: 20.3 | AB32: 0.525 | AC32: 9.2 | AD32: =IF(F32=0,0,Z32/F32) -> 21.379747 | AE32: =IFERROR(LEFT(C32,FIND("-",C32)-1),C32) -> PF | AF32: =B32&"|"&A32 -> Antawn Jamison|2008 | AG32: =SUMPRODUCT(($A$2:$A$4670=A32)*($Z$2:$Z$4670>Z32))+1 -> 14
A33: 2008 | B33: Anthony Carter | C33: PG | D33: 32 | E33: DEN | F33: 70 | G33: 67 | H33: 1960 | I33: 218 | J33: 476 | K33: 0.458 | L33: 45 | M33: 129 | N33: 0.349 | O33: 64 | P33: 85 | Q33: 0.753 | R33: 27 | S33: 173 | T33: 200 | U33: 388 | V33: 107 | W33: 28 | X33: 124 | Y33: 172 | Z33: 545 | AA33: 12.8 | AB33: 0.531 | AC33: 3.8 | AD33: =IF(F33=0,0,Z33/F33) -> 7.7857143 | AE33: =IFERROR(LEFT(C33,FIND("-",C33)-1),C33) -> PG | AF33: =B33&"|"&A33 -> Anthony Carter|2008 | AG33: =SUMPRODUCT(($A$2:$A$4670=A33)*($Z$2:$Z$4670>Z33))+1 -> 188
A34: 2008 | B34: Anthony Johnson | C34: PG | D34: 33 | E34: TOT | F34: 69 | G34: 52 | H34: 1531 | I34: 155 | J34: 355 | K34: 0.437 | L34: 42 | M34: 93 | N34: 0.452 | O34: 35 | P34: 43 | Q34: 0.814 | R34: 22 | S34: 115 | T34: 137 | U34: 262 | V34: 52 | W34: 9 | X34: 84 | Y34: 115 | Z34: 387 | AA34: 11.2 | AB34: 0.517 | AC34: 2 | AD34: =IF(F34=0,0,Z34/F34) -> 5.6086957 | AE34: =IFERROR(LEFT(C34,FIND("-",C34)-1),C34) -> PG | AF34: =B34&"|"&A34 -> Anthony Johnson|2008 | AG34: =SUMPRODUCT(($A$2:$A$4670=A34)*($Z$2:$Z$4670>Z34))+1 -> 238
A35: 2008 | B35: Anthony Parker | C35: SG | D35: 32 | E35: TOR | F35: 82 | G35: 82 | H35: 2634 | I35: 395 | J35: 829 | K35: 0.476 | L35: 133 | M35: 304 | N35: 0.438 | O35: 102 | P35: 125 | Q35: 0.816 | R35: 50 | S35: 284 | T35: 334 | U35: 183 | V35: 79 | W35: 17 | X35: 87 | Y35: 157 | Z35: 1025 | AA35: 14.4 | AB35: 0.58 | AC35: 6.2 | AD35: =IF(F35=0,0,Z35/F35) -> 12.5 | AE35: =IFERROR(LEFT(C35,FIND("-",C35)-1),C35) -> SG | AF35: =B35&"|"&A35 -> Anthony Parker|2008 | AG35: =SUMPRODUCT(($A$2:$A$4670=A35)*($Z$2:$Z$4670>Z35))+1 -> 76
A36: 2008 | B36: Antoine Walker | C36: PF | D36: 31 | E36: MIN | F36: 46 | G36: 1 | H36: 892 | I36: 136 | J36: 375 | K36: 0.363 | L36: 61 | M36: 188 | N36: 0.324 | O36: 35 | P36: 66 | Q36: 0.53 | R36: 56 | S36: 112 | T36: 168 | U36: 45 | V36: 33 | W36: 8 | X36: 46 | Y36: 80 | Z36: 368 | AA36: 11.4 | AB36: 0.455 | AC36: 0.1 | AD36: =IF(F36=0,0,Z36/F36) -> 8 | AE36: =IFERROR(LEFT(C36,FIND("-",C36)-1),C36) -> PF | AF36: =B36&"|"&A36 -> Antoine Walker|2008 | AG36: =SUMPRODUCT(($A$2:$A$4670=A36)*($Z$2:$Z$4670>Z36))+1 -> 242
A37: 2008 | B37: Antoine Wright | C37: SG | D37: 23 | E37: TOT | F37: 56 | G37: 10 | H37: 1232 | I37: 136 | J37: 329 | K37: 0.413 | L37: 32 | M37: 110 | N37: 0.291 | O37: 46 | P37: 67 | Q37: 0.687 | R37: 40 | S37: 107 | T37: 147 | U37: 80 | V37: 28 | W37: 21 | X37: 50 | Y37: 127 | Z37: 350 | AA37: 8.4 | AB37: 0.488 | AC37: 0.8 | AD37: =IF(F37=0,0,Z37/F37) -> 6.25 | AE37: =IFERROR(LEFT(C37,FIND("-",C37)-1),C37) -> SG | AF37: =B37&"|"&A37 -> Antoine Wright|2008 | AG37: =SUMPRODUCT(($A$2:$A$4670=A37)*($Z$2:$Z$4670>Z37))+1 -> 246
A38: 2008 | B38: Antonio Daniels | C38: PG | D38: 32 | E38: WAS | F38: 71 | G38: 63 | H38: 2161 | I38: 205 | J38: 447 | K38: 0.459 | L38: 17 | M38: 74 | N38: 0.23 | O38: 170 | P38: 219 | Q38: 0.776 | R38: 23 | S38: 180 | T38: 203 | U38: 340 | V38: 69 | W38: 2 | X38: 91 | Y38: 78 | Z38: 597 | AA38: 13.7 | AB38: 0.549 | AC38: 4.5 | AD38: =IF(F38=0,0,Z38/F38) -> 8.4084507 | AE38: =IFERROR(LEFT(C38,FIND("-",C38)-1),C38) -> PG | AF38: =B38&"|"&A38 -> Antonio Daniels|2008 | AG38: =SUMPRODUCT(($A$2:$A$4670=A38)*($Z$2:$Z$4670>Z38))+1 -> 169
A39: 2008 | B39: Antonio McDyess | C39: PF | D39: 33 | E39: DET | F39: 78 | G39: 78 | H39: 2285 | I39: 293 | J39: 600 | K39: 0.488 | L39: 0 | M39: 2 | N39: 0 | O39: 97 | P39: 156 | Q39: 0.622 | R39: 204 | S39: 462 | T39: 666 | U39: 89 | V39: 61 | W39: 53 | X39: 75 | Y39: 246 | Z39: 683 | AA39: 14.1 | AB39: 0.511 | AC39: 6.7 | AD39: =IF(F39=0,0,Z39/F39) -> 8.7564103 | AE39: =IFERROR(LEFT(C39,FIND("-",C39)-1),C39) -> PF | AF39: =B39&"|"&A39 -> Antonio McDyess|2008 | AG39: =SUMPRODUCT(($A$2:$A$4670=A39)*($Z$2:$Z$4670>Z39))+1 -> 148
A40: 2008 | B40: Arron Afflalo | C40: SG | D40: 22 | E40: DET | F40: 75 | G40: 9 | H40: 970 | I40: 99 | J40: 241 | K40: 0.411 | L40: 10 | M40: 48 | N40: 0.208 | O40: 68 | P40: 87 | Q40: 0.782 | R40: 36 | S40: 101 | T40: 137 | U40: 52 | V40: 31 | W40: 8 | X40: 34 | Y40: 83 | Z40: 276 | AA40: 10.2 | AB40: 0.494 | AC40: 1.9 | AD40: =IF(F40=0,0,Z40/F40) -> 3.68 | AE40: =IFERROR(LEFT(C40,FIND("-",C40)-1),C40) -> SG | AF40: =B40&"|"&A40 -> Arron Afflalo|2008 | AG40: =SUMPRODUCT(($A$2:$A$4670=A40)*($Z$2:$Z$4670>Z40))+1 -> 269
...

Sheet Player Lookup
A1: PLAYER LOOKUP TOOL
A2: Type a player name and season below to pull their full stat line.
B4: Player Name: | C4: LeBron James
B5: Season: | C5: 2017
B7: Lookup Key: | C7: =C4&"|"&C5 -> LeBron James|2017
B9: Stat | C9: Value
B10: Position | C10: =IFERROR(INDEX('Raw Data'!$C:$C,MATCH($C$7,'Raw Data'!$AF:$AF,0)),"Not found") -> SF
B11: Team | C11: =IFERROR(INDEX('Raw Data'!$E:$E,MATCH($C$7,'Raw Data'!$AF:$AF,0)),"Not found") -> CLE
B12: Age | C12: =IFERROR(INDEX('Raw Data'!$D:$D,MATCH($C$7,'Raw Data'!$AF:$AF,0)),"Not found") -> 32
B13: Games Played | C13: =IFERROR(INDEX('Raw Data'!$F:$F,MATCH($C$7,'Raw Data'!$AF:$AF,0)),"Not found") -> 74
B14: Season Total Points | C14: =IFERROR(INDEX('Raw Data'!$Z:$Z,MATCH($C$7,'Raw Data'!$AF:$AF,0)),"Not found") -> 1954
B15: Points Per Game | C15: =IFERROR(INDEX('Raw Data'!$AD:$AD,MATCH($C$7,'Raw Data'!$AF:$AF,0)),"Not found") -> 26.405405
B16: Total Rebounds | C16: =IFERROR(INDEX('Raw Data'!$T:$T,MATCH($C$7,'Raw Data'!$AF:$AF,0)),"Not found") -> 640
B17: Assists | C17: =IFERROR(INDEX('Raw Data'!$U:$U,MATCH($C$7,'Raw Data'!$AF:$AF,0)),"Not found") -> 646
B18: Steals | C18: =IFERROR(INDEX('Raw Data'!$V:$V,MATCH($C$7,'Raw Data'!$AF:$AF,0)),"Not found") -> 92
B19: Blocks | C19: =IFERROR(INDEX('Raw Data'!$W:$W,MATCH($C$7,'Raw Data'!$AF:$AF,0)),"Not found") -> 44
B20: FG% | C20: =IFERROR(INDEX('Raw Data'!$K:$K,MATCH($C$7,'Raw Data'!$AF:$AF,0)),"Not found") -> 0.548
B21: 3P% | C21: =IFERROR(INDEX('Raw Data'!$N:$N,MATCH($C$7,'Raw Data'!$AF:$AF,0)),"Not found") -> 0.363
B22: FT% | C22: =IFERROR(INDEX('Raw Data'!$Q:$Q,MATCH($C$7,'Raw Data'!$AF:$AF,0)),"Not found") -> 0.674
B23: PER | C23: =IFERROR(INDEX('Raw Data'!$AA:$AA,MATCH($C$7,'Raw Data'!$AF:$AF,0)),"Not found") -> 27
B24: True Shooting % | C24: =IFERROR(INDEX('Raw Data'!$AB:$AB,MATCH($C$7,'Raw Data'!$AF:$AF,0)),"Not found") -> 0.619
B25: Win Shares | C25: =IFERROR(INDEX('Raw Data'!$AC:$AC,MATCH($C$7,'Raw Data'!$AF:$AF,0)),"Not found") -> 12.9
B26: Season Rank by PTS | C26: =IFERROR(INDEX('Raw Data'!$AG:$AG,MATCH($C$7,'Raw Data'!$AF:$AF,0)),"Not found") -> 9

Sheet Season Rankings
A1: SEASON RANKINGS & LEAGUE SUMMARY
A2: Change the season below to refresh every figure on this sheet.
B4: Season: | C4: 2017
B6: Total Players (this season) | D6: =COUNTIF('Raw Data'!$A:$A,$C$4) -> 486
B7: League Avg PPG | D7: =AVERAGEIFS('Raw Data'!$AD:$AD,'Raw Data'!$A:$A,$C$4) -> 8.4263069
B8: League Avg Rebounds | D8: =AVERAGEIFS('Raw Data'!$T:$T,'Raw Data'!$A:$A,$C$4) -> 220.29218
B9: Players Averaging 25+ PPG | D9: =COUNTIFS('Raw Data'!$A:$A,$C$4,'Raw Data'!$AD:$AD,">=25") -> 13
B10: Total League Points Scored | D10: =SUMIF('Raw Data'!$A:$A,$C$4,'Raw Data'!$Z:$Z) -> 259753
B11: Highest Scorer (PTS) | D11: =_xlfn.MAXIFS('Raw Data'!$Z:$Z,'Raw Data'!$A:$A,$C$4) -> 2558
B13: Featured Player Comparison
B14: Featured Player | C14: Rank (Season) | D14: PTS | E14: PPG
B15: LeBron James | C15: =IFERROR(INDEX('Raw Data'!$AG:$AG,MATCH(B15&"|"&$C$4,'Raw Data'!$AF:$AF,0)),"N/A") -> 9 | D15: =IFERROR(INDEX('Raw Data'!$Z:$Z,MATCH(B15&"|"&$C$4,'Raw Data'!$AF:$AF,0)),"N/A") -> 1954 | E15: =IFERROR(INDEX('Raw Data'!$AD:$AD,MATCH(B15&"|"&$C$4,'Raw Data'!$AF:$AF,0)),"N/A") -> 26.405405
B16: Kevin Durant | C16: =IFERROR(INDEX('Raw Data'!$AG:$AG,MATCH(B16&"|"&$C$4,'Raw Data'!$AF:$AF,0)),"N/A") -> 25 | D16: =IFERROR(INDEX('Raw Data'!$Z:$Z,MATCH(B16&"|"&$C$4,'Raw Data'!$AF:$AF,0)),"N/A") -> 1555 | E16: =IFERROR(INDEX('Raw Data'!$AD:$AD,MATCH(B16&"|"&$C$4,'Raw Data'!$AF:$AF,0)),"N/A") -> 25.080645
B17: Dirk Nowitzki | C17: =IFERROR(INDEX('Raw Data'!$AG:$AG,MATCH(B17&"|"&$C$4,'Raw Data'!$AF:$AF,0)),"N/A") -> 124 | D17: =IFERROR(INDEX('Raw Data'!$Z:$Z,MATCH(B17&"|"&$C$4,'Raw Data'!$AF:$AF,0)),"N/A") -> 769 | E17: =IFERROR(INDEX('Raw Data'!$AD:$AD,MATCH(B17&"|"&$C$4,'Raw Data'!$AF:$AF,0)),"N/A") -> 14.240741
B18: Dwyane Wade | C18: =IFERROR(INDEX('Raw Data'!$AG:$AG,MATCH(B18&"|"&$C$4,'Raw Data'!$AF:$AF,0)),"N/A") -> 60 | D18: =IFERROR(INDEX('Raw Data'!$Z:$Z,MATCH(B18&"|"&$C$4,'Raw Data'!$AF:$AF,0)),"N/A") -> 1096 | E18: =IFERROR(INDEX('Raw Data'!$AD:$AD,MATCH(B18&"|"&$C$4,'Raw Data'!$AF:$AF,0)),"N/A") -> 18.266667
B19: Chris Paul | C19: =IFERROR(INDEX('Raw Data'!$AG:$AG,MATCH(B19&"|"&$C$4,'Raw Data'!$AF:$AF,0)),"N/A") -> 59 | D19: =IFERROR(INDEX('Raw Data'!$Z:$Z,MATCH(B19&"|"&$C$4,'Raw Data'!$AF:$AF,0)),"N/A") -> 1104 | E19: =IFERROR(INDEX('Raw Data'!$AD:$AD,MATCH(B19&"|"&$C$4,'Raw Data'!$AF:$AF,0)),"N/A") -> 18.098361

Sheet Position Averages
A1: POSITION AVERAGES & LEAGUE TRENDS
A2: All seasons (2008-2017) combined, grouped by primary position.
B4: Position | C4: Players (Count) | D4: Avg PPG | E4: Avg TRB | F4: Avg AST | G4: Avg FG% | I4: Filter
B5: PG | C5: =COUNTIF('Raw Data'!$AE:$AE,$B5) -> 890 | D5: =AVERAGEIFS('Raw Data'!$AD:$AD,'Raw Data'!$AE:$AE,$B5) -> 8.9733963 | E5: =AVERAGEIFS('Raw Data'!$T:$T,'Raw Data'!$AE:$AE,$B5) -> 140.47303 | F5: =AVERAGEIFS('Raw Data'!$U:$U,'Raw Data'!$AE:$AE,$B5) -> 235.18427 | G5: =AVERAGEIFS('Raw Data'!$K:$K,'Raw Data'!$AE:$AE,$B5) -> 0.4086509
B6: SG | C6: =COUNTIF('Raw Data'!$AE:$AE,$B6) -> 973 | D6: =AVERAGEIFS('Raw Data'!$AD:$AD,'Raw Data'!$AE:$AE,$B6) -> 8.9580262 | E6: =AVERAGEIFS('Raw Data'!$T:$T,'Raw Data'!$AE:$AE,$B6) -> 148.20041 | F6: =AVERAGEIFS('Raw Data'!$U:$U,'Raw Data'!$AE:$AE,$B6) -> 116.02158 | G6: =AVERAGEIFS('Raw Data'!$K:$K,'Raw Data'!$AE:$AE,$B6) -> 0.40941195 | I6: PrimaryPos | J6: Data
B7: SF | C7: =COUNTIF('Raw Data'!$AE:$AE,$B7) -> 895 | D7: =AVERAGEIFS('Raw Data'!$AD:$AD,'Raw Data'!$AE:$AE,$B7) -> 8.35259 | E7: =AVERAGEIFS('Raw Data'!$T:$T,'Raw Data'!$AE:$AE,$B7) -> 205.68715 | F7: =AVERAGEIFS('Raw Data'!$U:$U,'Raw Data'!$AE:$AE,$B7) -> 92.827933 | G7: =AVERAGEIFS('Raw Data'!$K:$K,'Raw Data'!$AE:$AE,$B7) -> 0.42135874 | I7: C
B8: PF | C8: =COUNTIF('Raw Data'!$AE:$AE,$B8) -> 955 | D8: =AVERAGEIFS('Raw Data'!$AD:$AD,'Raw Data'!$AE:$AE,$B8) -> 7.9377294 | E8: =AVERAGEIFS('Raw Data'!$T:$T,'Raw Data'!$AE:$AE,$B8) -> 286.63141 | F8: =AVERAGEIFS('Raw Data'!$U:$U,'Raw Data'!$AE:$AE,$B8) -> 69.08377 | G8: =AVERAGEIFS('Raw Data'!$K:$K,'Raw Data'!$AE:$AE,$B8) -> 0.45932563 | J8: Average - PTS | K8: 433.1318
B9: C | C9: =COUNTIF('Raw Data'!$AE:$AE,$B9) -> 956 | D9: =AVERAGEIFS('Raw Data'!$AD:$AD,'Raw Data'!$AE:$AE,$B9) -> 7.0320292 | E9: =AVERAGEIFS('Raw Data'!$T:$T,'Raw Data'!$AE:$AE,$B9) -> 309.19665 | F9: =AVERAGEIFS('Raw Data'!$U:$U,'Raw Data'!$AE:$AE,$B9) -> 56.09205 | G9: =AVERAGEIFS('Raw Data'!$K:$K,'Raw Data'!$AE:$AE,$B9) -> 0.49919203 | J9: Average - TRB | K9: 309.19665
J10: Average - AST | K10: 56.09205
I11: PF
J12: Average - PTS | K12: 504.35079
J13: Average - TRB | K13: 286.63141
J14: Average - AST | K14: 69.08377
I15: PG
J16: Average - PTS | K16: 561.79888
J17: Average - TRB | K17: 140.47303
J18: Average - AST | K18: 235.18427
I19: SF
J20: Average - PTS | K20: 531.67374
J21: Average - TRB | K21: 205.68715
J22: Average - AST | K22: 92.827933
I23: SG
J24: Average - PTS | K24: 565.67009
J25: Average - TRB | K25: 148.20041
J26: Average - AST | K26: 116.02158
I27: Total Average - PTS | K27: 518.73528
I28: Total Average - TRB | K28: 219.02656
I29: Total Average - AST | K29: 112.41872

Sheet Player Projections
A1: PLAYER STAT PROJECTIONS
A2: FORECAST.LINEAR projects each player's 2018 PPG from their 2008-2017 trend.
A4: Season | B4: LeBron James | C4: Kevin Durant | D4: Dirk Nowitzki | E4: Dwyane Wade | F4: Chris Paul
A5: 2008 | B5: =IFERROR(INDEX('Raw Data'!$AD:$AD,MATCH(B$4&"|"&$A5,'Raw Data'!$AF:$AF,0)),"") -> 30 | C5: =IFERROR(INDEX('Raw Data'!$AD:$AD,MATCH(C$4&"|"&$A5,'Raw Data'!$AF:$AF,0)),"") -> 20.3 | D5: =IFERROR(INDEX('Raw Data'!$AD:$AD,MATCH(D$4&"|"&$A5,'Raw Data'!$AF:$AF,0)),"") -> 23.597403 | E5: =IFERROR(INDEX('Raw Data'!$AD:$AD,MATCH(E$4&"|"&$A5,'Raw Data'!$AF:$AF,0)),"") -> 24.588235 | F5: =IFERROR(INDEX('Raw Data'!$AD:$AD,MATCH(F$4&"|"&$A5,'Raw Data'!$AF:$AF,0)),"") -> 21.05
A6: 2009 | B6: =IFERROR(INDEX('Raw Data'!$AD:$AD,MATCH(B$4&"|"&$A6,'Raw Data'!$AF:$AF,0)),"") -> 28.444444 | C6: =IFERROR(INDEX('Raw Data'!$AD:$AD,MATCH(C$4&"|"&$A6,'Raw Data'!$AF:$AF,0)),"") -> 25.283784 | D6: =IFERROR(INDEX('Raw Data'!$AD:$AD,MATCH(D$4&"|"&$A6,'Raw Data'!$AF:$AF,0)),"") -> 25.851852 | E6: =IFERROR(INDEX('Raw Data'!$AD:$AD,MATCH(E$4&"|"&$A6,'Raw Data'!$AF:$AF,0)),"") -> 30.202532 | F6: =IFERROR(INDEX('Raw Data'!$AD:$AD,MATCH(F$4&"|"&$A6,'Raw Data'!$AF:$AF,0)),"") -> 22.833333
A7: 2010 | B7: =IFERROR(INDEX('Raw Data'!$AD:$AD,MATCH(B$4&"|"&$A7,'Raw Data'!$AF:$AF,0)),"") -> 29.710526 | C7: =IFERROR(INDEX('Raw Data'!$AD:$AD,MATCH(C$4&"|"&$A7,'Raw Data'!$AF:$AF,0)),"") -> 30.146341 | D7: =IFERROR(INDEX('Raw Data'!$AD:$AD,MATCH(D$4&"|"&$A7,'Raw Data'!$AF:$AF,0)),"") -> 25.024691 | E7: =IFERROR(INDEX('Raw Data'!$AD:$AD,MATCH(E$4&"|"&$A7,'Raw Data'!$AF:$AF,0)),"") -> 26.558442 | F7: =IFERROR(INDEX('Raw Data'!$AD:$AD,MATCH(F$4&"|"&$A7,'Raw Data'!$AF:$AF,0)),"") -> 18.688889
A8: 2011 | B8: =IFERROR(INDEX('Raw Data'!$AD:$AD,MATCH(B$4&"|"&$A8,'Raw Data'!$AF:$AF,0)),"") -> 26.721519 | C8: =IFERROR(INDEX('Raw Data'!$AD:$AD,MATCH(C$4&"|"&$A8,'Raw Data'!$AF:$AF,0)),"") -> 27.705128 | D8: =IFERROR(INDEX('Raw Data'!$AD:$AD,MATCH(D$4&"|"&$A8,'Raw Data'!$AF:$AF,0)),"") -> 23.027397 | E8: =IFERROR(INDEX('Raw Data'!$AD:$AD,MATCH(E$4&"|"&$A8,'Raw Data'!$AF:$AF,0)),"") -> 25.539474 | F8: =IFERROR(INDEX('Raw Data'!$AD:$AD,MATCH(F$4&"|"&$A8,'Raw Data'!$AF:$AF,0)),"") -> 15.85
A9: 2012 | B9: =IFERROR(INDEX('Raw Data'!$AD:$AD,MATCH(B$4&"|"&$A9,'Raw Data'!$AF:$AF,0)),"") -> 27.145161 | C9: =IFERROR(INDEX('Raw Data'!$AD:$AD,MATCH(C$4&"|"&$A9,'Raw Data'!$AF:$AF,0)),"") -> 28.030303 | D9: =IFERROR(INDEX('Raw Data'!$AD:$AD,MATCH(D$4&"|"&$A9,'Raw Data'!$AF:$AF,0)),"") -> 21.645161 | E9: =IFERROR(INDEX('Raw Data'!$AD:$AD,MATCH(E$4&"|"&$A9,'Raw Data'!$AF:$AF,0)),"") -> 22.081633 | F9: =IFERROR(INDEX('Raw Data'!$AD:$AD,MATCH(F$4&"|"&$A9,'Raw Data'!$AF:$AF,0)),"") -> 19.816667
A10: 2013 | B10: =IFERROR(INDEX('Raw Data'!$AD:$AD,MATCH(B$4&"|"&$A10,'Raw Data'!$AF:$AF,0)),"") -> 26.789474 | C10: =IFERROR(INDEX('Raw Data'!$AD:$AD,MATCH(C$4&"|"&$A10,'Raw Data'!$AF:$AF,0)),"") -> 28.148148 | D10: =IFERROR(INDEX('Raw Data'!$AD:$AD,MATCH(D$4&"|"&$A10,'Raw Data'!$AF:$AF,0)),"") -> 17.301887 | E10: =IFERROR(INDEX('Raw Data'!$AD:$AD,MATCH(E$4&"|"&$A10,'Raw Data'!$AF:$AF,0)),"") -> 21.202899 | F10: =IFERROR(INDEX('Raw Data'!$AD:$AD,MATCH(F$4&"|"&$A10,'Raw Data'!$AF:$AF,0)),"") -> 16.942857
A11: 2014 | B11: =IFERROR(INDEX('Raw Data'!$AD:$AD,MATCH(B$4&"|"&$A11,'Raw Data'!$AF:$AF,0)),"") -> 27.12987 | C11: =IFERROR(INDEX('Raw Data'!$AD:$AD,MATCH(C$4&"|"&$A11,'Raw Data'!$AF:$AF,0)),"") -> 32.012346 | D11: =IFERROR(INDEX('Raw Data'!$AD:$AD,MATCH(D$4&"|"&$A11,'Raw Data'!$AF:$AF,0)),"") -> 21.6875 | E11: =IFERROR(INDEX('Raw Data'!$AD:$AD,MATCH(E$4&"|"&$A11,'Raw Data'!$AF:$AF,0)),"") -> 19.037037 | F11: =IFERROR(INDEX('Raw Data'!$AD:$AD,MATCH(F$4&"|"&$A11,'Raw Data'!$AF:$AF,0)),"") -> 19.112903
A12: 2015 | B12: =IFERROR(INDEX('Raw Data'!$AD:$AD,MATCH(B$4&"|"&$A12,'Raw Data'!$AF:$AF,0)),"") -> 25.26087 | C12: =IFERROR(INDEX('Raw Data'!$AD:$AD,MATCH(C$4&"|"&$A12,'Raw Data'!$AF:$AF,0)),"") -> 25.407407 | D12: =IFERROR(INDEX('Raw Data'!$AD:$AD,MATCH(D$4&"|"&$A12,'Raw Data'!$AF:$AF,0)),"") -> 17.311688 | E12: =IFERROR(INDEX('Raw Data'!$AD:$AD,MATCH(E$4&"|"&$A12,'Raw Data'!$AF:$AF,0)),"") -> 21.467742 | F12: =IFERROR(INDEX('Raw Data'!$AD:$AD,MATCH(F$4&"|"&$A12,'Raw Data'!$AF:$AF,0)),"") -> 19.073171
A13: 2016 | B13: =IFERROR(INDEX('Raw Data'!$AD:$AD,MATCH(B$4&"|"&$A13,'Raw Data'!$AF:$AF,0)),"") -> 25.263158 | C13: =IFERROR(INDEX('Raw Data'!$AD:$AD,MATCH(C$4&"|"&$A13,'Raw Data'!$AF:$AF,0)),"") -> 28.180556 | D13: =IFERROR(INDEX('Raw Data'!$AD:$AD,MATCH(D$4&"|"&$A13,'Raw Data'!$AF:$AF,0)),"") -> 18.293333 | E13: =IFERROR(INDEX('Raw Data'!$AD:$AD,MATCH(E$4&"|"&$A13,'Raw Data'!$AF:$AF,0)),"") -> 19.040541 | F13: =IFERROR(INDEX('Raw Data'!$AD:$AD,MATCH(F$4&"|"&$A13,'Raw Data'!$AF:$AF,0)),"") -> 19.540541
A14: 2017 | B14: =IFERROR(INDEX('Raw Data'!$AD:$AD,MATCH(B$4&"|"&$A14,'Raw Data'!$AF:$AF,0)),"") -> 26.405405 | C14: =IFERROR(INDEX('Raw Data'!$AD:$AD,MATCH(C$4&"|"&$A14,'Raw Data'!$AF:$AF,0)),"") -> 25.080645 | D14: =IFERROR(INDEX('Raw Data'!$AD:$AD,MATCH(D$4&"|"&$A14,'Raw Data'!$AF:$AF,0)),"") -> 14.240741 | E14: =IFERROR(INDEX('Raw Data'!$AD:$AD,MATCH(E$4&"|"&$A14,'Raw Data'!$AF:$AF,0)),"") -> 18.266667 | F14: =IFERROR(INDEX('Raw Data'!$AD:$AD,MATCH(F$4&"|"&$A14,'Raw Data'!$AF:$AF,0)),"") -> 18.098361
A15: 2018 | B15: =_xlfn.FORECAST.LINEAR(2018,B5:B14,$A5:$A14) -> 24.753734 | C15: =_xlfn.FORECAST.LINEAR(2018,C5:C14,$A5:$A14) -> 28.7844 | D15: =_xlfn.FORECAST.LINEAR(2018,D5:D14,$A5:$A14) -> 14.663246 | E15: =_xlfn.FORECAST.LINEAR(2018,E5:E14,$A5:$A14) -> 16.7696 | F15: =_xlfn.FORECAST.LINEAR(2018,F5:F14,$A5:$A14) -> 17.741406
