Workbook

Sheet README
A1: NFL Betting Trends -- Portfolio Project
A2: Data analyst portfolio piece | Built in Excel (openpyxl + native pivot tables)
A4: Data Source
A5: "NFL scores and betting data" -- Kaggle dataset by tobycrabtree. https://www.kaggle.com/datasets/tobycrabtree/nfl-scores-and-betting-data
A6: Filtered to the 2010-2017 regular and post-season (2,136 games). The original spreadspoke_scores.csv has no team-abbreviation column, so the Team Reference sheet was hand-built from public NFL franchise history and checked against the distinct HomeTeam/AwayTeam/FavoriteTeamID values that actually appear in this slice, to guarantee every VLOOKUP resolves cleanly with no broken matches.
A8: Why this dataset
A9: Betting-line data forces a different lookup problem than a typical "look up a name" exercise: team identity is split across two different coding schemes (full names vs. abbreviations) that have to be reconciled before any team-level analysis works. That makes VLOOKUP the natural tool here, instead of force-fitting it in.
A11: Technique Map
A12: Technique / Function | B12: Sheet | C12: Cell(s) | D12: Purpose
A13: VLOOKUP | B13: Raw Data | C13: M2, N2 (cols M-N) | D13: Translates full team names into the abbreviation scheme used by FavoriteTeamID.
A14: Nested IF | B14: Raw Data | C14: O2, R2 (Winner, FavoriteSide) | D14: Derives the game winner and which side was favored.
A15: Nested IF (nested 3 deep) | B15: Raw Data | C15: T2 (ATSResult) | D15: Determines whether the favorite covered the spread, using the spread-sign convention.
A16: IF | B16: Raw Data | C16: U2 (OUResult) | D16: Compares final score total against the Over/Under line.
A17: COUNTIF | B17: Team Performance Summary | C17: B5:C36 | D17: Games played and wins per team, combining home + away counts.
A18: AVERAGEIF | B18: Team Performance Summary | C18: E5:E36 | D18: Average home scoring margin per team.
A19: COUNTIFS (2 & 3 criteria) | B19: Team Performance Summary | C19: F5:G36 | D19: Times favored, and cover rate when favored, per team.
A20: Conditional formatting (color scale) | B20: Team Performance Summary | C20: D5:D36, H5:H36 | D20: Highlights best/worst win % and cover rate.
A21: COUNTIF / COUNTIFS | B21: Trends by Season | C21: B6:F13 | D21: Season-level game, Over, and ATS-cover counts.
A22: Native Pivot Table | B22: Trends by Season | C22: I4 | D22: Game count cross-tabbed by Season x Over/Under result.
A23: Line Chart | B23: Trends by Season | C23: below table | D23: Visualizes the Over Rate trend across seasons.
A26: Tip: click any formula cell across this workbook -- cells with a small red corner marker have a comment explaining the technique used, in addition to this map.

Sheet Team Reference
A1: TEAM NAME -> ABBREVIATION REFERENCE
A2: Manually compiled by the analyst from public NFL franchise history; not part of the original Kaggle file.
A4: Team Name | B4: Abbreviation
A5: Arizona Cardinals | B5: ARI
A6: Atlanta Falcons | B6: ATL
A7: Baltimore Ravens | B7: BAL
A8: Buffalo Bills | B8: BUF
A9: Carolina Panthers | B9: CAR
A10: Chicago Bears | B10: CHI
A11: Cincinnati Bengals | B11: CIN
A12: Cleveland Browns | B12: CLE
A13: Dallas Cowboys | B13: DAL
A14: Denver Broncos | B14: DEN
A15: Detroit Lions | B15: DET
... A38: Washington Redskins | B38: WAS

Sheet Raw Data
A1: Date | B1: Season | C1: Week | D1: HomeTeam | E1: AwayTeam | F1: HomeScore | G1: AwayScore | H1: FavoriteTeamID | I1: SpreadFavorite | J1: OverUnderLine | K1: Stadium | L1: IsPlayoff | M1: HomeAbbrev | N1: AwayAbbrev | O1: Winner | P1: HomeMargin | Q1: TotalPoints | R1: FavoriteSide | S1: FavoriteMargin | T1: ATSResult | U1: OUResult
A2: 09/09/2010 | B2: 2010 | C2: 1 | D2: New Orleans Saints | E2: Minnesota Vikings | F2: 14 | G2: 9 | H2: NO | I2: -5 | J2: 49.5 | K2: Louisiana Superdome | L2: =FALSE() -> FALSE | M2: =VLOOKUP(D2,'Team Reference'!$A:$B,2,FALSE()) -> NO | N2: =VLOOKUP(E2,'Team Reference'!$A:$B,2,FALSE()) -> MIN | O2: =IF(F2>G2,M2,IF(G2>F2,N2,"Tie")) -> NO | P2: =F2-G2 -> 5 | Q2: =F2+G2 -> 23 | R2: =IF(H2=M2,"Home",IF(H2=N2,"Away",IF(H2="PICK","Pick","N/A"))) -> Home | S2: =IF(R2="Home",P2,IF(R2="Away",-P2,"")) -> 5 | T2: =IF(R2="Pick","No Line",IF(S2="","N/A",IF(S2+I2>0,"Favorite Covered",IF(S2+I2<0,"Underdog Covered","Push")))) -> Push | U2: =IF(Q2>J2,"Over",IF(Q2<J2,"Under","Push")) -> Under
A3: 09/12/2010 | B3: 2010 | C3: 1 | D3: Buffalo Bills | E3: Miami Dolphins | F3: 10 | G3: 15 | H3: MIA | I3: -3 | J3: 39 | K3: Ralph Wilson Stadium | L3: =FALSE() -> FALSE | M3: =VLOOKUP(D3,'Team Reference'!$A:$B,2,FALSE()) -> BUF | N3: =VLOOKUP(E3,'Team Reference'!$A:$B,2,FALSE()) -> MIA | O3: =IF(F3>G3,M3,IF(G3>F3,N3,"Tie")) -> MIA | P3: =F3-G3 -> -5 | Q3: =F3+G3 -> 25 | R3: =IF(H3=M3,"Home",IF(H3=N3,"Away",IF(H3="PICK","Pick","N/A"))) -> Away | S3: =IF(R3="Home",P3,IF(R3="Away",-P3,"")) -> 5 | T3: =IF(R3="Pick","No Line",IF(S3="","N/A",IF(S3+I3>0,"Favorite Covered",IF(S3+I3<0,"Underdog Covered","Push")))) -> Favorite Covered | U3: =IF(Q3>J3,"Over",IF(Q3<J3,"Under","Push")) -> Under
A4: 09/12/2010 | B4: 2010 | C4: 1 | D4: Chicago Bears | E4: Detroit Lions | F4: 19 | G4: 14 | H4: CHI | I4: -6.5 | J4: 45 | K4: Soldier Field | L4: =FALSE() -> FALSE | M4: =VLOOKUP(D4,'Team Reference'!$A:$B,2,FALSE()) -> CHI | N4: =VLOOKUP(E4,'Team Reference'!$A:$B,2,FALSE()) -> DET | O4: =IF(F4>G4,M4,IF(G4>F4,N4,"Tie")) -> CHI | P4: =F4-G4 -> 5 | Q4: =F4+G4 -> 33 | R4: =IF(H4=M4,"Home",IF(H4=N4,"Away",IF(H4="PICK","Pick","N/A"))) -> Home | S4: =IF(R4="Home",P4,IF(R4="Away",-P4,"")) -> 5 | T4: =IF(R4="Pick","No Line",IF(S4="","N/A",IF(S4+I4>0,"Favorite Covered",IF(S4+I4<0,"Underdog Covered","Push")))) -> Underdog Covered | U4: =IF(Q4>J4,"Over",IF(Q4<J4,"Under","Push")) -> Under
A5: 09/12/2010 | B5: 2010 | C5: 1 | D5: Houston Texans | E5: Indianapolis Colts | F5: 34 | G5: 24 | H5: IND | I5: -1 | J5: 48 | K5: Reliant Stadium | L5: =FALSE() -> FALSE | M5: =VLOOKUP(D5,'Team Reference'!$A:$B,2,FALSE()) -> HOU | N5: =VLOOKUP(E5,'Team Reference'!$A:$B,2,FALSE()) -> IND | O5: =IF(F5>G5,M5,IF(G5>F5,N5,"Tie")) -> HOU | P5: =F5-G5 -> 10 | Q5: =F5+G5 -> 58 | R5: =IF(H5=M5,"Home",IF(H5=N5,"Away",IF(H5="PICK","Pick","N/A"))) -> Away | S5: =IF(R5="Home",P5,IF(R5="Away",-P5,"")) -> -10 | T5: =IF(R5="Pick","No Line",IF(S5="","N/A",IF(S5+I5>0,"Favorite Covered",IF(S5+I5<0,"Underdog Covered","Push")))) -> Underdog Covered | U5: =IF(Q5>J5,"Over",IF(Q5<J5,"Under","Push")) -> Over
A6: 09/12/2010 | B6: 2010 | C6: 1 | D6: Jacksonville Jaguars | E6: Denver Broncos | F6: 24 | G6: 17 | H6: JAX | I6: -3 | J6: 41.5 | K6: EverBank Field | L6: =FALSE() -> FALSE | M6: =VLOOKUP(D6,'Team Reference'!$A:$B,2,FALSE()) -> JAX | N6: =VLOOKUP(E6,'Team Reference'!$A:$B,2,FALSE()) -> DEN | O6: =IF(F6>G6,M6,IF(G6>F6,N6,"Tie")) -> JAX | P6: =F6-G6 -> 7 | Q6: =F6+G6 -> 41 | R6: =IF(H6=M6,"Home",IF(H6=N6,"Away",IF(H6="PICK","Pick","N/A"))) -> Home | S6: =IF(R6="Home",P6,IF(R6="Away",-P6,"")) -> 7 | T6: =IF(R6="Pick","No Line",IF(S6="","N/A",IF(S6+I6>0,"Favorite Covered",IF(S6+I6<0,"Underdog Covered","Push")))) -> Favorite Covered | U6: =IF(Q6>J6,"Over",IF(Q6<J6,"Under","Push")) -> Under
A7: 09/12/2010 | B7: 2010 | C7: 1 | D7: New England Patriots | E7: Cincinnati Bengals | F7: 38 | G7: 24 | H7: NE | I7: -5.5 | J7: 45 | K7: Gillette Stadium | L7: =FALSE() -> FALSE | M7: =VLOOKUP(D7,'Team Reference'!$A:$B,2,FALSE()) -> NE | N7: =VLOOKUP(E7,'Team Reference'!$A:$B,2,FALSE()) -> CIN | O7: =IF(F7>G7,M7,IF(G7>F7,N7,"Tie")) -> NE | P7: =F7-G7 -> 14 | Q7: =F7+G7 -> 62 | R7: =IF(H7=M7,"Home",IF(H7=N7,"Away",IF(H7="PICK","Pick","N/A"))) -> Home | S7: =IF(R7="Home",P7,IF(R7="Away",-P7,"")) -> 14 | T7: =IF(R7="Pick","No Line",IF(S7="","N/A",IF(S7+I7>0,"Favorite Covered",IF(S7+I7<0,"Underdog Covered","Push")))) -> Favorite Covered | U7: =IF(Q7>J7,"Over",IF(Q7<J7,"Under","Push")) -> Over
A8: 09/12/2010 | B8: 2010 | C8: 1 | D8: New York Giants | E8: Carolina Panthers | F8: 31 | G8: 18 | H8: NYG | I8: -6 | J8: 41 | K8: MetLife Stadium | L8: =FALSE() -> FALSE | M8: =VLOOKUP(D8,'Team Reference'!$A:$B,2,FALSE()) -> NYG | N8: =VLOOKUP(E8,'Team Reference'!$A:$B,2,FALSE()) -> CAR | O8: =IF(F8>G8,M8,IF(G8>F8,N8,"Tie")) -> NYG | P8: =F8-G8 -> 13 | Q8: =F8+G8 -> 49 | R8: =IF(H8=M8,"Home",IF(H8=N8,"Away",IF(H8="PICK","Pick","N/A"))) -> Home | S8: =IF(R8="Home",P8,IF(R8="Away",-P8,"")) -> 13 | T8: =IF(R8="Pick","No Line",IF(S8="","N/A",IF(S8+I8>0,"Favorite Covered",IF(S8+I8<0,"Underdog Covered","Push")))) -> Favorite Covered | U8: =IF(Q8>J8,"Over",IF(Q8<J8,"Under","Push")) -> Over
A9: 09/12/2010 | B9: 2010 | C9: 1 | D9: Philadelphia Eagles | E9: Green Bay Packers | F9: 20 | G9: 27 | H9: GB | I9: -3 | J9: 48 | K9: Lincoln Financial Field | L9: =FALSE() -> FALSE | M9: =VLOOKUP(D9,'Team Reference'!$A:$B,2,FALSE()) -> PHI | N9: =VLOOKUP(E9,'Team Reference'!$A:$B,2,FALSE()) -> GB | O9: =IF(F9>G9,M9,IF(G9>F9,N9,"Tie")) -> GB | P9: =F9-G9 -> -7 | Q9: =F9+G9 -> 47 | R9: =IF(H9=M9,"Home",IF(H9=N9,"Away",IF(H9="PICK","Pick","N/A"))) -> Away | S9: =IF(R9="Home",P9,IF(R9="Away",-P9,"")) -> 7 | T9: =IF(R9="Pick","No Line",IF(S9="","N/A",IF(S9+I9>0,"Favorite Covered",IF(S9+I9<0,"Underdog Covered","Push")))) -> Favorite Covered | U9: =IF(Q9>J9,"Over",IF(Q9<J9,"Under","Push")) -> Under
A10: 09/12/2010 | B10: 2010 | C10: 1 | D10: Pittsburgh Steelers | E10: Atlanta Falcons | F10: 15 | G10: 9 | H10: ATL | I10: -1.5 | J10: 39.5 | K10: Heinz Field | L10: =FALSE() -> FALSE | M10: =VLOOKUP(D10,'Team Reference'!$A:$B,2,FALSE()) -> PIT | N10: =VLOOKUP(E10,'Team Reference'!$A:$B,2,FALSE()) -> ATL | O10: =IF(F10>G10,M10,IF(G10>F10,N10,"Tie")) -> PIT | P10: =F10-G10 -> 6 | Q10: =F10+G10 -> 24 | R10: =IF(H10=M10,"Home",IF(H10=N10,"Away",IF(H10="PICK","Pick","N/A"))) -> Away | S10: =IF(R10="Home",P10,IF(R10="Away",-P10,"")) -> -6 | T10: =IF(R10="Pick","No Line",IF(S10="","N/A",IF(S10+I10>0,"Favorite Covered",IF(S10+I10<0,"Underdog Covered","Push")))) -> Underdog Covered | U10: =IF(Q10>J10,"Over",IF(Q10<J10,"Under","Push")) -> Under
A11: 09/12/2010 | B11: 2010 | C11: 1 | D11: Seattle Seahawks | E11: San Francisco 49ers | F11: 31 | G11: 6 | H11: SF | I11: -3 | J11: 37 | K11: CenturyLink Field | L11: =FALSE() -> FALSE | M11: =VLOOKUP(D11,'Team Reference'!$A:$B,2,FALSE()) -> SEA | N11: =VLOOKUP(E11,'Team Reference'!$A:$B,2,FALSE()) -> SF | O11: =IF(F11>G11,M11,IF(G11>F11,N11,"Tie")) -> SEA | P11: =F11-G11 -> 25 | Q11: =F11+G11 -> 37 | R11: =IF(H11=M11,"Home",IF(H11=N11,"Away",IF(H11="PICK","Pick","N/A"))) -> Away | S11: =IF(R11="Home",P11,IF(R11="Away",-P11,"")) -> -25 | T11: =IF(R11="Pick","No Line",IF(S11="","N/A",IF(S11+I11>0,"Favorite Covered",IF(S11+I11<0,"Underdog Covered","Push")))) -> Underdog Covered | U11: =IF(Q11>J11,"Over",IF(Q11<J11,"Under","Push")) -> Push
A12: 09/12/2010 | B12: 2010 | C12: 1 | D12: St. Louis Rams | E12: Arizona Cardinals | F12: 13 | G12: 17 | H12: ARI | I12: -3 | J12: 39.5 | K12: Edward Jones Dome | L12: =FALSE() -> FALSE | M12: =VLOOKUP(D12,'Team Reference'!$A:$B,2,FALSE()) -> LAR | N12: =VLOOKUP(E12,'Team Reference'!$A:$B,2,FALSE()) -> ARI | O12: =IF(F12>G12,M12,IF(G12>F12,N12,"Tie")) -> ARI | P12: =F12-G12 -> -4 | Q12: =F12+G12 -> 30 | R12: =IF(H12=M12,"Home",IF(H12=N12,"Away",IF(H12="PICK","Pick","N/A"))) -> Away | S12: =IF(R12="Home",P12,IF(R12="Away",-P12,"")) -> 4 | T12: =IF(R12="Pick","No Line",IF(S12="","N/A",IF(S12+I12>0,"Favorite Covered",IF(S12+I12<0,"Underdog Covered","Push")))) -> Favorite Covered | U12: =IF(Q12>J12,"Over",IF(Q12<J12,"Under","Push")) -> Under
A13: 09/12/2010 | B13: 2010 | C13: 1 | D13: Tampa Bay Buccaneers | E13: Cleveland Browns | F13: 17 | G13: 14 | H13: TB | I13: -2.5 | J13: 37 | K13: Raymond James Stadium | L13: =FALSE() -> FALSE | M13: =VLOOKUP(D13,'Team Reference'!$A:$B,2,FALSE()) -> TB | N13: =VLOOKUP(E13,'Team Reference'!$A:$B,2,FALSE()) -> CLE | O13: =IF(F13>G13,M13,IF(G13>F13,N13,"Tie")) -> TB | P13: =F13-G13 -> 3 | Q13: =F13+G13 -> 31 | R13: =IF(H13=M13,"Home",IF(H13=N13,"Away",IF(H13="PICK","Pick","N/A"))) -> Home | S13: =IF(R13="Home",P13,IF(R13="Away",-P13,"")) -> 3 | T13: =IF(R13="Pick","No Line",IF(S13="","N/A",IF(S13+I13>0,"Favorite Covered",IF(S13+I13<0,"Underdog Covered","Push")))) -> Favorite Covered | U13: =IF(Q13>J13,"Over",IF(Q13<J13,"Under","Push")) -> Under
... A257: 01/02/2011 | B257: 2010 | C257: 17 | D257: Washington Redskins | E257: New York Giants | F257: 14 | G257: 17 | H257: NYG | I257: -4 | J257: 44.5 | K257: FedExField | L257: =FALSE() -> FALSE | M257: =VLOOKUP(D257,'Team Reference'!$A:$B,2,FALSE()) -> WAS | N257: =VLOOKUP(E257,'Team Reference'!$A:$B,2,FALSE()) -> NYG | O257: =IF(F257>G257,M257,IF(G257>F257,N257,"Tie")) -> NYG | P257: =F257-G257 -> -3 | Q257: =F257+G257 -> 31 | R257: =IF(H257=M257,"Home",IF(H257=N257,"Away",IF(H257="PICK","Pick","N/A"))) -> Away | S257: =IF(R257="Home",P257,IF(R257="Away",-P257,"")) -> 3 | T257: =IF(R257="Pick","No Line",IF(S257="","N/A",IF(S257+I257>0,"Favorite Covered",IF(S257+I257<0,"Underdog Covered","Push")))) -> Underdog Covered | U257: =IF(Q257>J257,"Over",IF(Q257<J257,"Under","Push")) -> Under
A258: 01/08/2011 | B258: 2010 | C258: Wildcard | D258: Indianapolis Colts | E258: New York Jets | F258: 16 | G258: 17 | H258: IND | I258: -2 | J258: 44.5 | L258: =TRUE() -> TRUE | M258: =VLOOKUP(D258,'Team Reference'!$A:$B,2,FALSE()) -> IND | N258: =VLOOKUP(E258,'Team Reference'!$A:$B,2,FALSE()) -> NYJ | O258: =IF(F258>G258,M258,IF(G258>F258,N258,"Tie")) -> NYJ | P258: =F258-G258 -> -1 | Q258: =F258+G258 -> 33 | R258: =IF(H258=M258,"Home",IF(H258=N258,"Away",IF(H258="PICK","Pick","N/A"))) -> Home | S258: =IF(R258="Home",P258,IF(R258="Away",-P258,"")) -> -1 | T258: =IF(R258="Pick","No Line",IF(S258="","N/A",IF(S258+I258>0,"Favorite Covered",IF(S258+I258<0,"Underdog Covered","Push")))) -> Underdog Covered | U258: =IF(Q258>J258,"Over",IF(Q258<J258,"Under","Push")) -> Under
A259: 01/08/2011 | B259: 2010 | C259: Wildcard | D259: Seattle Seahawks | E259: New Orleans Saints | F259: 41 | G259: 36 | H259: NO | I259: -10 | J259: 46 | L259: =TRUE() -> TRUE | M259: =VLOOKUP(D259,'Team Reference'!$A:$B,2,FALSE()) -> SEA | N259: =VLOOKUP(E259,'Team Reference'!$A:$B,2,FALSE()) -> NO | O259: =IF(F259>G259,M259,IF(G259>F259,N259,"Tie")) -> SEA | P259: =F259-G259 -> 5 | Q259: =F259+G259 -> 77 | R259: =IF(H259=M259,"Home",IF(H259=N259,"Away",IF(H259="PICK","Pick","N/A"))) -> Away | S259: =IF(R259="Home",P259,IF(R259="Away",-P259,"")) -> -5 | T259: =IF(R259="Pick","No Line",IF(S259="","N/A",IF(S259+I259>0,"Favorite Covered",IF(S259+I259<0,"Underdog Covered","Push")))) -> Underdog Covered | U259: =IF(Q259>J259,"Over",IF(Q259<J259,"Under","Push")) -> Over
A260: 01/09/2011 | B260: 2010 | C260: Wildcard | D260: Kansas City Chiefs | E260: Baltimore Ravens | F260: 7 | G260: 30 | H260: BAL | I260: -3 | J260: 41 | L260: =TRUE() -> TRUE | M260: =VLOOKUP(D260,'Team Reference'!$A:$B,2,FALSE()) -> KC | N260: =VLOOKUP(E260,'Team Reference'!$A:$B,2,FALSE()) -> BAL | O260: =IF(F260>G260,M260,IF(G260>F260,N260,"Tie")) -> BAL | P260: =F260-G260 -> -23 | Q260: =F260+G260 -> 37 | R260: =IF(H260=M260,"Home",IF(H260=N260,"Away",IF(H260="PICK","Pick","N/A"))) -> Away | S260: =IF(R260="Home",P260,IF(R260="Away",-P260,"")) -> 23 | T260: =IF(R260="Pick","No Line",IF(S260="","N/A",IF(S260+I260>0,"Favorite Covered",IF(S260+I260<0,"Underdog Covered","Push")))) -> Favorite Covered | U260: =IF(Q260>J260,"Over",IF(Q260<J260,"Under","Push")) -> Under
A261: 01/09/2011 | B261: 2010 | C261: Wildcard | D261: Philadelphia Eagles | E261: Green Bay Packers | F261: 16 | G261: 21 | H261: PHI | I261: -2.5 | J261: 47 | L261: =TRUE() -> TRUE | M261: =VLOOKUP(D261,'Team Reference'!$A:$B,2,FALSE()) -> PHI | N261: =VLOOKUP(E261,'Team Reference'!$A:$B,2,FALSE()) -> GB | O261: =IF(F261>G261,M261,IF(G261>F261,N261,"Tie")) -> GB | P261: =F261-G261 -> -5 | Q261: =F261+G261 -> 37 | R261: =IF(H261=M261,"Home",IF(H261=N261,"Away",IF(H261="PICK","Pick","N/A"))) -> Home | S261: =IF(R261="Home",P261,IF(R261="Away",-P261,"")) -> -5 | T261: =IF(R261="Pick","No Line",IF(S261="","N/A",IF(S261+I261>0,"Favorite Covered",IF(S261+I261<0,"Underdog Covered","Push")))) -> Underdog Covered | U261: =IF(Q261>J261,"Over",IF(Q261<J261,"Under","Push")) -> Under
A262: 01/15/2011 | B262: 2010 | C262: Division | D262: Atlanta Falcons | E262: Green Bay Packers | F262: 21 | G262: 48 | H262: ATL | I262: -1.5 | J262: 43.5 | K262: Georgia Dome | L262: =TRUE() -> TRUE | M262: =VLOOKUP(D262,'Team Reference'!$A:$B,2,FALSE()) -> ATL | N262: =VLOOKUP(E262,'Team Reference'!$A:$B,2,FALSE()) -> GB | O262: =IF(F262>G262,M262,IF(G262>F262,N262,"Tie")) -> GB | P262: =F262-G262 -> -27 | Q262: =F262+G262 -> 69 | R262: =IF(H262=M262,"Home",IF(H262=N262,"Away",IF(H262="PICK","Pick","N/A"))) -> Home | S262: =IF(R262="Home",P262,IF(R262="Away",-P262,"")) -> -27 | T262: =IF(R262="Pick","No Line",IF(S262="","N/A",IF(S262+I262>0,"Favorite Covered",IF(S262+I262<0,"Underdog Covered","Push")))) -> Underdog Covered | U262: =IF(Q262>J262,"Over",IF(Q262<J262,"Under","Push")) -> Over
A263: 01/15/2011 | B263: 2010 | C263: Division | D263: Pittsburgh Steelers | E263: Baltimore Ravens | F263: 31 | G263: 24 | H263: PIT | I263: -3 | J263: 37 | L263: =TRUE() -> TRUE | M263: =VLOOKUP(D263,'Team Reference'!$A:$B,2,FALSE()) -> PIT | N263: =VLOOKUP(E263,'Team Reference'!$A:$B,2,FALSE()) -> BAL | O263: =IF(F263>G263,M263,IF(G263>F263,N263,"Tie")) -> PIT | P263: =F263-G263 -> 7 | Q263: =F263+G263 -> 55 | R263: =IF(H263=M263,"Home",IF(H263=N263,"Away",IF(H263="PICK","Pick","N/A"))) -> Home | S263: =IF(R263="Home",P263,IF(R263="Away",-P263,"")) -> 7 | T263: =IF(R263="Pick","No Line",IF(S263="","N/A",IF(S263+I263>0,"Favorite Covered",IF(S263+I263<0,"Underdog Covered","Push")))) -> Favorite Covered | U263: =IF(Q263>J263,"Over",IF(Q263<J263,"Under","Push")) -> Over
A264: 01/16/2011 | B264: 2010 | C264: Division | D264: Chicago Bears | E264: Seattle Seahawks | F264: 35 | G264: 24 | H264: CHI | I264: -10 | J264: 43 | K264: Soldier Field | L264: =TRUE() -> TRUE | M264: =VLOOKUP(D264,'Team Reference'!$A:$B,2,FALSE()) -> CHI | N264: =VLOOKUP(E264,'Team Reference'!$A:$B,2,FALSE()) -> SEA | O264: =IF(F264>G264,M264,IF(G264>F264,N264,"Tie")) -> CHI | P264: =F264-G264 -> 11 | Q264: =F264+G264 -> 59 | R264: =IF(H264=M264,"Home",IF(H264=N264,"Away",IF(H264="PICK","Pick","N/A"))) -> Home | S264: =IF(R264="Home",P264,IF(R264="Away",-P264,"")) -> 11 | T264: =IF(R264="Pick","No Line",IF(S264="","N/A",IF(S264+I264>0,"Favorite Covered",IF(S264+I264<0,"Underdog Covered","Push")))) -> Favorite Covered | U264: =IF(Q264>J264,"Over",IF(Q264<J264,"Under","Push")) -> Over
A265: 01/16/2011 | B265: 2010 | C265: Division | D265: New England Patriots | E265: New York Jets | F265: 21 | G265: 28 | H265: NE | I265: -9.5 | J265: 45 | L265: =TRUE() -> TRUE | M265: =VLOOKUP(D265,'Team Reference'!$A:$B,2,FALSE()) -> NE | N265: =VLOOKUP(E265,'Team Reference'!$A:$B,2,FALSE()) -> NYJ | O265: =IF(F265>G265,M265,IF(G265>F265,N265,"Tie")) -> NYJ | P265: =F265-G265 -> -7 | Q265: =F265+G265 -> 49 | R265: =IF(H265=M265,"Home",IF(H265=N265,"Away",IF(H265="PICK","Pick","N/A"))) -> Home | S265: =IF(R265="Home",P265,IF(R265="Away",-P265,"")) -> -7 | T265: =IF(R265="Pick","No Line",IF(S265="","N/A",IF(S265+I265>0,"Favorite Covered",IF(S265+I265<0,"Underdog Covered","Push")))) -> Underdog Covered | U265: =IF(Q265>J265,"Over",IF(Q265<J265,"Under","Push")) -> Over
A266: 01/23/2011 | B266: 2010 | C266: Conference | D266: Chicago Bears | E266: Green Bay Packers | F266: 14 | G266: 21 | H266: GB | I266: -3.5 | J266: 42.5 | K266: Soldier Field | L266: =TRUE() -> TRUE | M266: =VLOOKUP(D266,'Team Reference'!$A:$B,2,FALSE()) -> CHI | N266: =VLOOKUP(E266,'Team Reference'!$A:$B,2,FALSE()) -> GB | O266: =IF(F266>G266,M266,IF(G266>F266,N266,"Tie")) -> GB | P266: =F266-G266 -> -7 | Q266: =F266+G266 -> 35 | R266: =IF(H266=M266,"Home",IF(H266=N266,"Away",IF(H266="PICK","Pick","N/A"))) -> Away | S266: =IF(R266="Home",P266,IF(R266="Away",-P266,"")) -> 7 | T266: =IF(R266="Pick","No Line",IF(S266="","N/A",IF(S266+I266>0,"Favorite Covered",IF(S266+I266<0,"Underdog Covered","Push")))) -> Favorite Covered | U266: =IF(Q266>J266,"Over",IF(Q266<J266,"Under","Push")) -> Under
A267: 01/23/2011 | B267: 2010 | C267: Conference | D267: Pittsburgh Steelers | E267: New York Jets | F267: 24 | G267: 19 | H267: PIT | I267: -4 | J267: 38 | L267: =TRUE() -> TRUE | M267: =VLOOKUP(D267,'Team Reference'!$A:$B,2,FALSE()) -> PIT | N267: =VLOOKUP(E267,'Team Reference'!$A:$B,2,FALSE()) -> NYJ | O267: =IF(F267>G267,M267,IF(G267>F267,N267,"Tie")) -> PIT | P267: =F267-G267 -> 5 | Q267: =F267+G267 -> 43 | R267: =IF(H267=M267,"Home",IF(H267=N267,"Away",IF(H267="PICK","Pick","N/A"))) -> Home | S267: =IF(R267="Home",P267,IF(R267="Away",-P267,"")) -> 5 | T267: =IF(R267="Pick","No Line",IF(S267="","N/A",IF(S267+I267>0,"Favorite Covered",IF(S267+I267<0,"Underdog Covered","Push")))) -> Favorite Covered | U267: =IF(Q267>J267,"Over",IF(Q267<J267,"Under","Push")) -> Over
A268: 02/06/2011 | B268: 2010 | C268: Superbowl | D268: Green Bay Packers | E268: Pittsburgh Steelers | F268: 31 | G268: 25 | H268: GB | I268: -3 | J268: 45 | K268: Cowboys Stadium | L268: =TRUE() -> TRUE | M268: =VLOOKUP(D268,'Team Reference'!$A:$B,2,FALSE()) -> GB | N268: =VLOOKUP(E268,'Team Reference'!$A:$B,2,FALSE()) -> PIT | O268: =IF(F268>G268,M268,IF(G268>F268,N268,"Tie")) -> GB | P268: =F268-G268 -> 6 | Q268: =F268+G268 -> 56 | R268: =IF(H268=M268,"Home",IF(H268=N268,"Away",IF(H268="PICK","Pick","N/A"))) -> Home | S268: =IF(R268="Home",P268,IF(R268="Away",-P268,"")) -> 6 | T268: =IF(R268="Pick","No Line",IF(S268="","N/A",IF(S268+I268>0,"Favorite Covered",IF(S268+I268<0,"Underdog Covered","Push")))) -> Favorite Covered | U268: =IF(Q268>J268,"Over",IF(Q268<J268,"Under","Push")) -> Over
A269: 09/08/2011 | B269: 2011 | C269: 1 | D269: Green Bay Packers | E269: New Orleans Saints | F269: 42 | G269: 34 | H269: GB | I269: -5 | J269: 48 | K269: Lambeau Field | L269: =FALSE() -> FALSE | M269: =VLOOKUP(D269,'Team Reference'!$A:$B,2,FALSE()) -> GB | N269: =VLOOKUP(E269,'Team Reference'!$A:$B,2,FALSE()) -> NO | O269: =IF(F269>G269,M269,IF(G269>F269,N269,"Tie")) -> GB | P269: =F269-G269 -> 8 | Q269: =F269+G269 -> 76 | R269: =IF(H269=M269,"Home",IF(H269=N269,"Away",IF(H269="PICK","Pick","N/A"))) -> Home | S269: =IF(R269="Home",P269,IF(R269="Away",-P269,"")) -> 8 | T269: =IF(R269="Pick","No Line",IF(S269="","N/A",IF(S269+I269>0,"Favorite Covered",IF(S269+I269<0,"Underdog Covered","Push")))) -> Favorite Covered | U269: =IF(Q269>J269,"Over",IF(Q269<J269,"Under","Push")) -> Over
A270: 09/11/2011 | B270: 2011 | C270: 1 | D270: Arizona Cardinals | E270: Carolina Panthers | F270: 28 | G270: 21 | H270: ARI | I270: -7 | J270: 37.5 | K270: University of Phoenix Stadium | L270: =FALSE() -> FALSE | M270: =VLOOKUP(D270,'Team Reference'!$A:$B,2,FALSE()) -> ARI | N270: =VLOOKUP(E270,'Team Reference'!$A:$B,2,FALSE()) -> CAR | O270: =IF(F270>G270,M270,IF(G270>F270,N270,"Tie")) -> ARI | P270: =F270-G270 -> 7 | Q270: =F270+G270 -> 49 | R270: =IF(H270=M270,"Home",IF(H270=N270,"Away",IF(H270="PICK","Pick","N/A"))) -> Home | S270: =IF(R270="Home",P270,IF(R270="Away",-P270,"")) -> 7 | T270: =IF(R270="Pick","No Line",IF(S270="","N/A",IF(S270+I270>0,"Favorite Covered",IF(S270+I270<0,"Underdog Covered","Push")))) -> Push | U270: =IF(Q270>J270,"Over",IF(Q270<J270,"Under","Push")) -> Over
A271: 09/11/2011 | B271: 2011 | C271: 1 | D271: Baltimore Ravens | E271: Pittsburgh Steelers | F271: 35 | G271: 7 | H271: BAL | I271: -1.5 | J271: 37 | K271: M&T Bank Stadium | L271: =FALSE() -> FALSE | M271: =VLOOKUP(D271,'Team Reference'!$A:$B,2,FALSE()) -> BAL | N271: =VLOOKUP(E271,'Team Reference'!$A:$B,2,FALSE()) -> PIT | O271: =IF(F271>G271,M271,IF(G271>F271,N271,"Tie")) -> BAL | P271: =F271-G271 -> 28 | Q271: =F271+G271 -> 42 | R271: =IF(H271=M271,"Home",IF(H271=N271,"Away",IF(H271="PICK","Pick","N/A"))) -> Home | S271: =IF(R271="Home",P271,IF(R271="Away",-P271,"")) -> 28 | T271: =IF(R271="Pick","No Line",IF(S271="","N/A",IF(S271+I271>0,"Favorite Covered",IF(S271+I271<0,"Underdog Covered","Push")))) -> Favorite Covered | U271: =IF(Q271>J271,"Over",IF(Q271<J271,"Under","Push")) -> Over
A272: 09/11/2011 | B272: 2011 | C272: 1 | D272: Chicago Bears | E272: Atlanta Falcons | F272: 30 | G272: 12 | H272: ATL | I272: -1.5 | J272: 41 | K272: Soldier Field | L272: =FALSE() -> FALSE | M272: =VLOOKUP(D272,'Team Reference'!$A:$B,2,FALSE()) -> CHI | N272: =VLOOKUP(E272,'Team Reference'!$A:$B,2,FALSE()) -> ATL | O272: =IF(F272>G272,M272,IF(G272>F272,N272,"Tie")) -> CHI | P272: =F272-G272 -> 18 | Q272: =F272+G272 -> 42 | R272: =IF(H272=M272,"Home",IF(H272=N272,"Away",IF(H272="PICK","Pick","N/A"))) -> Away | S272: =IF(R272="Home",P272,IF(R272="Away",-P272,"")) -> -18 | T272: =IF(R272="Pick","No Line",IF(S272="","N/A",IF(S272+I272>0,"Favorite Covered",IF(S272+I272<0,"Underdog Covered","Push")))) -> Underdog Covered | U272: =IF(Q272>J272,"Over",IF(Q272<J272,"Under","Push")) -> Over
A273: 09/11/2011 | B273: 2011 | C273: 1 | D273: Cleveland Browns | E273: Cincinnati Bengals | F273: 17 | G273: 27 | H273: CLE | I273: -7 | J273: 36.5 | K273: FirstEnergy Stadium | L273: =FALSE() -> FALSE | M273: =VLOOKUP(D273,'Team Reference'!$A:$B,2,FALSE()) -> CLE | N273: =VLOOKUP(E273,'Team Reference'!$A:$B,2,FALSE()) -> CIN | O273: =IF(F273>G273,M273,IF(G273>F273,N273,"Tie")) -> CIN | P273: =F273-G273 -> -10 | Q273: =F273+G273 -> 44 | R273: =IF(H273=M273,"Home",IF(H273=N273,"Away",IF(H273="PICK","Pick","N/A"))) -> Home | S273: =IF(R273="Home",P273,IF(R273="Away",-P273,"")) -> -10 | T273: =IF(R273="Pick","No Line",IF(S273="","N/A",IF(S273+I273>0,"Favorite Covered",IF(S273+I273<0,"Underdog Covered","Push")))) -> Underdog Covered | U273: =IF(Q273>J273,"Over",IF(Q273<J273,"Under","Push")) -> Over
A274: 09/11/2011 | B274: 2011 | C274: 1 | D274: Houston Texans | E274: Indianapolis Colts | F274: 34 | G274: 7 | H274: HOU | I274: -9 | J274: 44 | K274: Reliant Stadium | L274: =FALSE() -> FALSE | M274: =VLOOKUP(D274,'Team Reference'!$A:$B,2,FALSE()) -> HOU | N274: =VLOOKUP(E274,'Team Reference'!$A:$B,2,FALSE()) -> IND | O274: =IF(F274>G274,M274,IF(G274>F274,N274,"Tie")) -> HOU | P274: =F274-G274 -> 27 | Q274: =F274+G274 -> 41 | R274: =IF(H274=M274,"Home",IF(H274=N274,"Away",IF(H274="PICK","Pick","N/A"))) -> Home | S274: =IF(R274="Home",P274,IF(R274="Away",-P274,"")) -> 27 | T274: =IF(R274="Pick","No Line",IF(S274="","N/A",IF(S274+I274>0,"Favorite Covered",IF(S274+I274<0,"Underdog Covered","Push")))) -> Favorite Covered | U274: =IF(Q274>J274,"Over",IF(Q274<J274,"Under","Push")) -> Under
A275: 09/11/2011 | B275: 2011 | C275: 1 | D275: Jacksonville Jaguars | E275: Tennessee Titans | F275: 16 | G275: 14 | H275: TEN | I275: -1.5 | J275: 38 | K275: EverBank Field | L275: =FALSE() -> FALSE | M275: =VLOOKUP(D275,'Team Reference'!$A:$B,2,FALSE()) -> JAX | N275: =VLOOKUP(E275,'Team Reference'!$A:$B,2,FALSE()) -> TEN | O275: =IF(F275>G275,M275,IF(G275>F275,N275,"Tie")) -> JAX | P275: =F275-G275 -> 2 | Q275: =F275+G275 -> 30 | R275: =IF(H275=M275,"Home",IF(H275=N275,"Away",IF(H275="PICK","Pick","N/A"))) -> Away | S275: =IF(R275="Home",P275,IF(R275="Away",-P275,"")) -> -2 | T275: =IF(R275="Pick","No Line",IF(S275="","N/A",IF(S275+I275>0,"Favorite Covered",IF(S275+I275<0,"Underdog Covered","Push")))) -> Underdog Covered | U275: =IF(Q275>J275,"Over",IF(Q275<J275,"Under","Push")) -> Under
A276: 09/11/2011 | B276: 2011 | C276: 1 | D276: Kansas City Chiefs | E276: Buffalo Bills | F276: 7 | G276: 41 | H276: KC | I276: -3.5 | J276: 40 | K276: Arrowhead Stadium | L276: =FALSE() -> FALSE | M276: =VLOOKUP(D276,'Team Reference'!$A:$B,2,FALSE()) -> KC | N276: =VLOOKUP(E276,'Team Reference'!$A:$B,2,FALSE()) -> BUF | O276: =IF(F276>G276,M276,IF(G276>F276,N276,"Tie")) -> BUF | P276: =F276-G276 -> -34 | Q276: =F276+G276 -> 48 | R276: =IF(H276=M276,"Home",IF(H276=N276,"Away",IF(H276="PICK","Pick","N/A"))) -> Home | S276: =IF(R276="Home",P276,IF(R276="Away",-P276,"")) -> -34 | T276: =IF(R276="Pick","No Line",IF(S276="","N/A",IF(S276+I276>0,"Favorite Covered",IF(S276+I276<0,"Underdog Covered","Push")))) -> Underdog Covered | U276: =IF(Q276>J276,"Over",IF(Q276<J276,"Under","Push")) -> Over
A277: 09/11/2011 | B277: 2011 | C277: 1 | D277: New York Jets | E277: Dallas Cowboys | F277: 27 | G277: 24 | H277: NYJ | I277: -6 | J277: 41 | K277: MetLife Stadium | L277: =FALSE() -> FALSE | M277: =VLOOKUP(D277,'Team Reference'!$A:$B,2,FALSE()) -> NYJ | N277: =VLOOKUP(E277,'Team Reference'!$A:$B,2,FALSE()) -> DAL | O277: =IF(F277>G277,M277,IF(G277>F277,N277,"Tie")) -> NYJ | P277: =F277-G277 -> 3 | Q277: =F277+G277 -> 51 | R277: =IF(H277=M277,"Home",IF(H277=N277,"Away",IF(H277="PICK","Pick","N/A"))) -> Home | S277: =IF(R277="Home",P277,IF(R277="Away",-P277,"")) -> 3 | T277: =IF(R277="Pick","No Line",IF(S277="","N/A",IF(S277+I277>0,"Favorite Covered",IF(S277+I277<0,"Underdog Covered","Push")))) -> Underdog Covered | U277: =IF(Q277>J277,"Over",IF(Q277<J277,"Under","Push")) -> Over
A278: 09/11/2011 | B278: 2011 | C278: 1 | D278: San Diego Chargers | E278: Minnesota Vikings | F278: 24 | G278: 17 | H278: LAC | I278: -8.5 | J278: 43 | K278: Qualcomm Stadium | L278: =FALSE() -> FALSE | M278: =VLOOKUP(D278,'Team Reference'!$A:$B,2,FALSE()) -> LAC | N278: =VLOOKUP(E278,'Team Reference'!$A:$B,2,FALSE()) -> MIN | O278: =IF(F278>G278,M278,IF(G278>F278,N278,"Tie")) -> LAC | P278: =F278-G278 -> 7 | Q278: =F278+G278 -> 41 | R278: =IF(H278=M278,"Home",IF(H278=N278,"Away",IF(H278="PICK","Pick","N/A"))) -> Home | S278: =IF(R278="Home",P278,IF(R278="Away",-P278,"")) -> 7 | T278: =IF(R278="Pick","No Line",IF(S278="","N/A",IF(S278+I278>0,"Favorite Covered",IF(S278+I278<0,"Underdog Covered","Push")))) -> Underdog Covered | U278: =IF(Q278>J278,"Over",IF(Q278<J278,"Under","Push")) -> Under
A279: 09/11/2011 | B279: 2011 | C279: 1 | D279: San Francisco 49ers | E279: Seattle Seahawks | F279: 33 | G279: 17 | H279: SF | I279: -6 | J279: 38 | K279: Candlestick Park | L279: =FALSE() -> FALSE | M279: =VLOOKUP(D279,'Team Reference'!$A:$B,2,FALSE()) -> SF | N279: =VLOOKUP(E279,'Team Reference'!$A:$B,2,FALSE()) -> SEA | O279: =IF(F279>G279,M279,IF(G279>F279,N279,"Tie")) -> SF | P279: =F279-G279 -> 16 | Q279: =F279+G279 -> 50 | R279: =IF(H279=M279,"Home",IF(H279=N279,"Away",IF(H279="PICK","Pick","N/A"))) -> Home | S279: =IF(R279="Home",P279,IF(R279="Away",-P279,"")) -> 16 | T279: =IF(R279="Pick","No Line",IF(S279="","N/A",IF(S279+I279>0,"Favorite Covered",IF(S279+I279<0,"Underdog Covered","Push")))) -> Favorite Covered | U279: =IF(Q279>J279,"Over",IF(Q279<J279,"Under","Push")) -> Over
A280: 09/11/2011 | B280: 2011 | C280: 1 | D280: St. Louis Rams | E280: Philadelphia Eagles | F280: 13 | G280: 31 | H280: PHI | I280: -4 | J280: 44.5 | K280: Edward Jones Dome | L280: =FALSE() -> FALSE | M280: =VLOOKUP(D280,'Team Reference'!$A:$B,2,FALSE()) -> LAR | N280: =VLOOKUP(E280,'Team Reference'!$A:$B,2,FALSE()) -> PHI | O280: =IF(F280>G280,M280,IF(G280>F280,N280,"Tie")) -> PHI | P280: =F280-G280 -> -18 | Q280: =F280+G280 -> 44 | R280: =IF(H280=M280,"Home",IF(H280=N280,"Away",IF(H280="PICK","Pick","N/A"))) -> Away | S280: =IF(R280="Home",P280,IF(R280="Away",-P280,"")) -> 18 | T280: =IF(R280="Pick","No Line",IF(S280="","N/A",IF(S280+I280>0,"Favorite Covered",IF(S280+I280<0,"Underdog Covered","Push")))) -> Favorite Covered | U280: =IF(Q280>J280,"Over",IF(Q280<J280,"Under","Push")) -> Under
... A524: 01/01/2012 | B524: 2011 | C524: 17 | D524: St. Louis Rams | E524: San Francisco 49ers | F524: 27 | G524: 34 | H524: SF | I524: -12.5 | J524: 34.5 | K524: Edward Jones Dome | L524: =FALSE() -> FALSE | M524: =VLOOKUP(D524,'Team Reference'!$A:$B,2,FALSE()) -> LAR | N524: =VLOOKUP(E524,'Team Reference'!$A:$B,2,FALSE()) -> SF | O524: =IF(F524>G524,M524,IF(G524>F524,N524,"Tie")) -> SF | P524: =F524-G524 -> -7 | Q524: =F524+G524 -> 61 | R524: =IF(H524=M524,"Home",IF(H524=N524,"Away",IF(H524="PICK","Pick","N/A"))) -> Away | S524: =IF(R524="Home",P524,IF(R524="Away",-P524,"")) -> 7 | T524: =IF(R524="Pick","No Line",IF(S524="","N/A",IF(S524+I524>0,"Favorite Covered",IF(S524+I524<0,"Underdog Covered","Push")))) -> Underdog Covered | U524: =IF(Q524>J524,"Over",IF(Q524<J524,"Under","Push")) -> Over
A525: 01/07/2012 | B525: 2011 | C525: Wildcard | D525: Houston Texans | E525: Cincinnati Bengals | F525: 31 | G525: 10 | H525: HOU | I525: -4 | J525: 38 | L525: =TRUE() -> TRUE | M525: =VLOOKUP(D525,'Team Reference'!$A:$B,2,FALSE()) -> HOU | N525: =VLOOKUP(E525,'Team Reference'!$A:$B,2,FALSE()) -> CIN | O525: =IF(F525>G525,M525,IF(G525>F525,N525,"Tie")) -> HOU | P525: =F525-G525 -> 21 | Q525: =F525+G525 -> 41 | R525: =IF(H525=M525,"Home",IF(H525=N525,"Away",IF(H525="PICK","Pick","N/A"))) -> Home | S525: =IF(R525="Home",P525,IF(R525="Away",-P525,"")) -> 21 | T525: =IF(R525="Pick","No Line",IF(S525="","N/A",IF(S525+I525>0,"Favorite Covered",IF(S525+I525<0,"Underdog Covered","Push")))) -> Favorite Covered | U525: =IF(Q525>J525,"Over",IF(Q525<J525,"Under","Push")) -> Over
A526: 01/07/2012 | B526: 2011 | C526: Wildcard | D526: New Orleans Saints | E526: Detroit Lions | F526: 45 | G526: 28 | H526: NO | I526: -10.5 | J526: 60 | L526: =TRUE() -> TRUE | M526: =VLOOKUP(D526,'Team Reference'!$A:$B,2,FALSE()) -> NO | N526: =VLOOKUP(E526,'Team Reference'!$A:$B,2,FALSE()) -> DET | O526: =IF(F526>G526,M526,IF(G526>F526,N526,"Tie")) -> NO | P526: =F526-G526 -> 17 | Q526: =F526+G526 -> 73 | R526: =IF(H526=M526,"Home",IF(H526=N526,"Away",IF(H526="PICK","Pick","N/A"))) -> Home | S526: =IF(R526="Home",P526,IF(R526="Away",-P526,"")) -> 17 | T526: =IF(R526="Pick","No Line",IF(S526="","N/A",IF(S526+I526>0,"Favorite Covered",IF(S526+I526<0,"Underdog Covered","Push")))) -> Favorite Covered | U526: =IF(Q526>J526,"Over",IF(Q526<J526,"Under","Push")) -> Over
...

Sheet Team Performance Summary
A1: TEAM PERFORMANCE SUMMARY (2010-2017)
A2: Aggregated by franchise abbreviation, so relocated franchises (Rams, Chargers) show one combined record.
A4: Team | B4: Games | C4: Wins | D4: Win % | E4: Avg Home Margin | F4: Times Favored | G4: Covers When Favored | H4: Cover Rate When Favored
A5: ARI | B5: =COUNTIF('Raw Data'!$M:$M,$A5)+COUNTIF('Raw Data'!$N:$N,$A5) -> 131 | C5: =COUNTIF('Raw Data'!$O:$O,$A5) -> 68 | D5: =IF(B5=0,0,C5/B5) -> 0.51908397 | E5: =IFERROR(AVERAGEIF('Raw Data'!$M:$M,$A5,'Raw Data'!$P:$P),"N/A") -> 3.4923077 | F5: =COUNTIFS('Raw Data'!$M:$M,$A5,'Raw Data'!$R:$R,"Home")+COUNTIFS('Raw Data'!$N:$N,$A5,'Raw Data'!$R:$R,"Away") -> 65 | G5: =COUNTIFS('Raw Data'!$M:$M,$A5,'Raw Data'!$R:$R,"Home",'Raw Data'!$T:$T,"Favorite Covered")+COUNTIFS('Raw Data'!$N:$N,$A5,'Raw Data'!$R:$R,"Away",'Raw Data'!$T:$T,"Favorite Covered") -> 28 | H5: =IF(F5=0,"N/A",G5/F5) -> 0.43076923
A6: ATL | B6: =COUNTIF('Raw Data'!$M:$M,$A6)+COUNTIF('Raw Data'!$N:$N,$A6) -> 137 | C6: =COUNTIF('Raw Data'!$O:$O,$A6) -> 79 | D6: =IF(B6=0,0,C6/B6) -> 0.57664234 | E6: =IFERROR(AVERAGEIF('Raw Data'!$M:$M,$A6,'Raw Data'!$P:$P),"N/A") -> 4.6376812 | F6: =COUNTIFS('Raw Data'!$M:$M,$A6,'Raw Data'!$R:$R,"Home")+COUNTIFS('Raw Data'!$N:$N,$A6,'Raw Data'!$R:$R,"Away") -> 88 | G6: =COUNTIFS('Raw Data'!$M:$M,$A6,'Raw Data'!$R:$R,"Home",'Raw Data'!$T:$T,"Favorite Covered")+COUNTIFS('Raw Data'!$N:$N,$A6,'Raw Data'!$R:$R,"Away",'Raw Data'!$T:$T,"Favorite Covered") -> 40 | H6: =IF(F6=0,"N/A",G6/F6) -> 0.45454545
A7: BAL | B7: =COUNTIF('Raw Data'!$M:$M,$A7)+COUNTIF('Raw Data'!$N:$N,$A7) -> 138 | C7: =COUNTIF('Raw Data'!$O:$O,$A7) -> 81 | D7: =IF(B7=0,0,C7/B7) -> 0.58695652 | E7: =IFERROR(AVERAGEIF('Raw Data'!$M:$M,$A7,'Raw Data'!$P:$P),"N/A") -> 6.7878788 | F7: =COUNTIFS('Raw Data'!$M:$M,$A7,'Raw Data'!$R:$R,"Home")+COUNTIFS('Raw Data'!$N:$N,$A7,'Raw Data'!$R:$R,"Away") -> 81 | G7: =COUNTIFS('Raw Data'!$M:$M,$A7,'Raw Data'!$R:$R,"Home",'Raw Data'!$T:$T,"Favorite Covered")+COUNTIFS('Raw Data'!$N:$N,$A7,'Raw Data'!$R:$R,"Away",'Raw Data'!$T:$T,"Favorite Covered") -> 34 | H7: =IF(F7=0,"N/A",G7/F7) -> 0.41975309
A8: BUF | B8: =COUNTIF('Raw Data'!$M:$M,$A8)+COUNTIF('Raw Data'!$N:$N,$A8) -> 129 | C8: =COUNTIF('Raw Data'!$O:$O,$A8) -> 55 | D8: =IF(B8=0,0,C8/B8) -> 0.42635659 | E8: =IFERROR(AVERAGEIF('Raw Data'!$M:$M,$A8,'Raw Data'!$P:$P),"N/A") -> 1.484375 | F8: =COUNTIFS('Raw Data'!$M:$M,$A8,'Raw Data'!$R:$R,"Home")+COUNTIFS('Raw Data'!$N:$N,$A8,'Raw Data'!$R:$R,"Away") -> 46 | G8: =COUNTIFS('Raw Data'!$M:$M,$A8,'Raw Data'!$R:$R,"Home",'Raw Data'!$T:$T,"Favorite Covered")+COUNTIFS('Raw Data'!$N:$N,$A8,'Raw Data'!$R:$R,"Away",'Raw Data'!$T:$T,"Favorite Covered") -> 21 | H8: =IF(F8=0,"N/A",G8/F8) -> 0.45652174
A9: CAR | B9: =COUNTIF('Raw Data'!$M:$M,$A9)+COUNTIF('Raw Data'!$N:$N,$A9) -> 135 | C9: =COUNTIF('Raw Data'!$O:$O,$A9) -> 69 | D9: =IF(B9=0,0,C9/B9) -> 0.51111111 | E9: =IFERROR(AVERAGEIF('Raw Data'!$M:$M,$A9,'Raw Data'!$P:$P),"N/A") -> 2.2941176 | F9: =COUNTIFS('Raw Data'!$M:$M,$A9,'Raw Data'!$R:$R,"Home")+COUNTIFS('Raw Data'!$N:$N,$A9,'Raw Data'!$R:$R,"Away") -> 75 | G9: =COUNTIFS('Raw Data'!$M:$M,$A9,'Raw Data'!$R:$R,"Home",'Raw Data'!$T:$T,"Favorite Covered")+COUNTIFS('Raw Data'!$N:$N,$A9,'Raw Data'!$R:$R,"Away",'Raw Data'!$T:$T,"Favorite Covered") -> 35 | H9: =IF(F9=0,"N/A",G9/F9) -> 0.46666667
A10: CHI | B10: =COUNTIF('Raw Data'!$M:$M,$A10)+COUNTIF('Raw Data'!$N:$N,$A10) -> 130 | C10: =COUNTIF('Raw Data'!$O:$O,$A10) -> 57 | D10: =IF(B10=0,0,C10/B10) -> 0.43846154 | E10: =IFERROR(AVERAGEIF('Raw Data'!$M:$M,$A10,'Raw Data'!$P:$P),"N/A") -> 0.03030303 | F10: =COUNTIFS('Raw Data'!$M:$M,$A10,'Raw Data'!$R:$R,"Home")+COUNTIFS('Raw Data'!$N:$N,$A10,'Raw Data'!$R:$R,"Away") -> 55 | G10: =COUNTIFS('Raw Data'!$M:$M,$A10,'Raw Data'!$R:$R,"Home",'Raw Data'!$T:$T,"Favorite Covered")+COUNTIFS('Raw Data'!$N:$N,$A10,'Raw Data'!$R:$R,"Away",'Raw Data'!$T:$T,"Favorite Covered") -> 19 | H10: =IF(F10=0,"N/A",G10/F10) -> 0.34545455
A11: CIN | B11: =COUNTIF('Raw Data'!$M:$M,$A11)+COUNTIF('Raw Data'!$N:$N,$A11) -> 133 | C11: =COUNTIF('Raw Data'!$O:$O,$A11) -> 69 | D11: =IF(B11=0,0,C11/B11) -> 0.51879699 | E11: =IFERROR(AVERAGEIF('Raw Data'!$M:$M,$A11,'Raw Data'!$P:$P),"N/A") -> 3.6212121 | F11: =COUNTIFS('Raw Data'!$M:$M,$A11,'Raw Data'!$R:$R,"Home")+COUNTIFS('Raw Data'!$N:$N,$A11,'Raw Data'!$R:$R,"Away") -> 69 | G11: =COUNTIFS('Raw Data'!$M:$M,$A11,'Raw Data'!$R:$R,"Home",'Raw Data'!$T:$T,"Favorite Covered")+COUNTIFS('Raw Data'!$N:$N,$A11,'Raw Data'!$R:$R,"Away",'Raw Data'!$T:$T,"Favorite Covered") -> 35 | H11: =IF(F11=0,"N/A",G11/F11) -> 0.50724638
A12: CLE | B12: =COUNTIF('Raw Data'!$M:$M,$A12)+COUNTIF('Raw Data'!$N:$N,$A12) -> 128 | C12: =COUNTIF('Raw Data'!$O:$O,$A12) -> 29 | D12: =IF(B12=0,0,C12/B12) -> 0.2265625 | E12: =IFERROR(AVERAGEIF('Raw Data'!$M:$M,$A12,'Raw Data'!$P:$P),"N/A") -> -5.265625 | F12: =COUNTIFS('Raw Data'!$M:$M,$A12,'Raw Data'!$R:$R,"Home")+COUNTIFS('Raw Data'!$N:$N,$A12,'Raw Data'!$R:$R,"Away") -> 27 | G12: =COUNTIFS('Raw Data'!$M:$M,$A12,'Raw Data'!$R:$R,"Home",'Raw Data'!$T:$T,"Favorite Covered")+COUNTIFS('Raw Data'!$N:$N,$A12,'Raw Data'!$R:$R,"Away",'Raw Data'!$T:$T,"Favorite Covered") -> 7 | H12: =IF(F12=0,"N/A",G12/F12) -> 0.25925926
A13: DAL | B13: =COUNTIF('Raw Data'!$M:$M,$A13)+COUNTIF('Raw Data'!$N:$N,$A13) -> 131 | C13: =COUNTIF('Raw Data'!$O:$O,$A13) -> 69 | D13: =IF(B13=0,0,C13/B13) -> 0.52671756 | E13: =IFERROR(AVERAGEIF('Raw Data'!$M:$M,$A13,'Raw Data'!$P:$P),"N/A") -> 1.1060606 | F13: =COUNTIFS('Raw Data'!$M:$M,$A13,'Raw Data'!$R:$R,"Home")+COUNTIFS('Raw Data'!$N:$N,$A13,'Raw Data'!$R:$R,"Away") -> 68 | G13: =COUNTIFS('Raw Data'!$M:$M,$A13,'Raw Data'!$R:$R,"Home",'Raw Data'!$T:$T,"Favorite Covered")+COUNTIFS('Raw Data'!$N:$N,$A13,'Raw Data'!$R:$R,"Away",'Raw Data'!$T:$T,"Favorite Covered") -> 26 | H13: =IF(F13=0,"N/A",G13/F13) -> 0.38235294
A14: DEN | B14: =COUNTIF('Raw Data'!$M:$M,$A14)+COUNTIF('Raw Data'!$N:$N,$A14) -> 138 | C14: =COUNTIF('Raw Data'!$O:$O,$A14) -> 82 | D14: =IF(B14=0,0,C14/B14) -> 0.5942029 | E14: =IFERROR(AVERAGEIF('Raw Data'!$M:$M,$A14,'Raw Data'!$P:$P),"N/A") -> 4.9863014 | F14: =COUNTIFS('Raw Data'!$M:$M,$A14,'Raw Data'!$R:$R,"Home")+COUNTIFS('Raw Data'!$N:$N,$A14,'Raw Data'!$R:$R,"Away") -> 76 | G14: =COUNTIFS('Raw Data'!$M:$M,$A14,'Raw Data'!$R:$R,"Home",'Raw Data'!$T:$T,"Favorite Covered")+COUNTIFS('Raw Data'!$N:$N,$A14,'Raw Data'!$R:$R,"Away",'Raw Data'!$T:$T,"Favorite Covered") -> 35 | H14: =IF(F14=0,"N/A",G14/F14) -> 0.46052632
A15: DET | B15: =COUNTIF('Raw Data'!$M:$M,$A15)+COUNTIF('Raw Data'!$N:$N,$A15) -> 131 | C15: =COUNTIF('Raw Data'!$O:$O,$A15) -> 63 | D15: =IF(B15=0,0,C15/B15) -> 0.48091603 | E15: =IFERROR(AVERAGEIF('Raw Data'!$M:$M,$A15,'Raw Data'!$P:$P),"N/A") -> 3.9375 | F15: =COUNTIFS('Raw Data'!$M:$M,$A15,'Raw Data'!$R:$R,"Home")+COUNTIFS('Raw Data'!$N:$N,$A15,'Raw Data'!$R:$R,"Away") -> 61 | G15: =COUNTIFS('Raw Data'!$M:$M,$A15,'Raw Data'!$R:$R,"Home",'Raw Data'!$T:$T,"Favorite Covered")+COUNTIFS('Raw Data'!$N:$N,$A15,'Raw Data'!$R:$R,"Away",'Raw Data'!$T:$T,"Favorite Covered") -> 28 | H15: =IF(F15=0,"N/A",G15/F15) -> 0.45901639
A16: GB | B16: =COUNTIF('Raw Data'!$M:$M,$A16)+COUNTIF('Raw Data'!$N:$N,$A16) -> 143 | C16: =COUNTIF('Raw Data'!$O:$O,$A16) -> 92 | D16: =IF(B16=0,0,C16/B16) -> 0.64335664 | E16: =IFERROR(AVERAGEIF('Raw Data'!$M:$M,$A16,'Raw Data'!$P:$P),"N/A") -> 9.3857143 | F16: =COUNTIFS('Raw Data'!$M:$M,$A16,'Raw Data'!$R:$R,"Home")+COUNTIFS('Raw Data'!$N:$N,$A16,'Raw Data'!$R:$R,"Away") -> 93 | G16: =COUNTIFS('Raw Data'!$M:$M,$A16,'Raw Data'!$R:$R,"Home",'Raw Data'!$T:$T,"Favorite Covered")+COUNTIFS('Raw Data'!$N:$N,$A16,'Raw Data'!$R:$R,"Away",'Raw Data'!$T:$T,"Favorite Covered") -> 52 | H16: =IF(F16=0,"N/A",G16/F16) -> 0.55913978
... A36: WAS | B36: =COUNTIF('Raw Data'!$M:$M,$A36)+COUNTIF('Raw Data'!$N:$N,$A36) -> 130 | C36: =COUNTIF('Raw Data'!$O:$O,$A36) -> 52 | D36: =IF(B36=0,0,C36/B36) -> 0.4 | E36: =IFERROR(AVERAGEIF('Raw Data'!$M:$M,$A36,'Raw Data'!$P:$P),"N/A") -> -2.1363636 | F36: =COUNTIFS('Raw Data'!$M:$M,$A36,'Raw Data'!$R:$R,"Home")+COUNTIFS('Raw Data'!$N:$N,$A36,'Raw Data'!$R:$R,"Away") -> 43 | G36: =COUNTIFS('Raw Data'!$M:$M,$A36,'Raw Data'!$R:$R,"Home",'Raw Data'!$T:$T,"Favorite Covered")+COUNTIFS('Raw Data'!$N:$N,$A36,'Raw Data'!$R:$R,"Away",'Raw Data'!$T:$T,"Favorite Covered") -> 14 | H36: =IF(F36=0,"N/A",G36/F36) -> 0.3255814

Sheet Trends by Season
A1: BETTING TRENDS BY SEASON
A2: Over/Under and against-the-spread outcomes, season by season.
A4: Season | B4: Games | C4: Over Count | D4: Over Rate | E4: Favorite Covers | F4: Decided ATS Games | G4: Favorite Cover Rate | I4: Filter
A5: 2010 | B5: =COUNTIF('Raw Data'!$B:$B,$A5) -> 267 | C5: =COUNTIFS('Raw Data'!$B:$B,$A5,'Raw Data'!$U:$U,"Over") -> 146 | D5: =IF(B5=0,0,C5/B5) -> 0.54681648 | E5: =COUNTIFS('Raw Data'!$B:$B,$A5,'Raw Data'!$T:$T,"Favorite Covered") -> 125 | F5: =COUNTIFS('Raw Data'!$B:$B,$A5,'Raw Data'!$T:$T,"Favorite Covered")+COUNTIFS('Raw Data'!$B:$B,$A5,'Raw Data'!$T:$T,"Underdog Covered") -> 257 | G5: =IF(F5=0,0,E5/F5) -> 0.48638132
A6: 2011 | B6: =COUNTIF('Raw Data'!$B:$B,$A6) -> 267 | C6: =COUNTIFS('Raw Data'!$B:$B,$A6,'Raw Data'!$U:$U,"Over") -> 130 | D6: =IF(B6=0,0,C6/B6) -> 0.48689139 | E6: =COUNTIFS('Raw Data'!$B:$B,$A6,'Raw Data'!$T:$T,"Favorite Covered") -> 121 | F6: =COUNTIFS('Raw Data'!$B:$B,$A6,'Raw Data'!$T:$T,"Favorite Covered")+COUNTIFS('Raw Data'!$B:$B,$A6,'Raw Data'!$T:$T,"Underdog Covered") -> 257 | G6: =IF(F6=0,0,E6/F6) -> 0.47081712 | I6: Count - Date | J6: OUResult
A7: 2012 | B7: =COUNTIF('Raw Data'!$B:$B,$A7) -> 267 | C7: =COUNTIFS('Raw Data'!$B:$B,$A7,'Raw Data'!$U:$U,"Over") -> 129 | D7: =IF(B7=0,0,C7/B7) -> 0.48314607 | E7: =COUNTIFS('Raw Data'!$B:$B,$A7,'Raw Data'!$T:$T,"Favorite Covered") -> 124 | F7: =COUNTIFS('Raw Data'!$B:$B,$A7,'Raw Data'!$T:$T,"Favorite Covered")+COUNTIFS('Raw Data'!$B:$B,$A7,'Raw Data'!$T:$T,"Underdog Covered") -> 261 | G7: =IF(F7=0,0,E7/F7) -> 0.47509579 | I7: Season | J7: Over | K7: Push | L7: Under | M7: Total Result
A8: 2013 | B8: =COUNTIF('Raw Data'!$B:$B,$A8) -> 267 | C8: =COUNTIFS('Raw Data'!$B:$B,$A8,'Raw Data'!$U:$U,"Over") -> 133 | D8: =IF(B8=0,0,C8/B8) -> 0.49812734 | E8: =COUNTIFS('Raw Data'!$B:$B,$A8,'Raw Data'!$T:$T,"Favorite Covered") -> 129 | F8: =COUNTIFS('Raw Data'!$B:$B,$A8,'Raw Data'!$T:$T,"Favorite Covered")+COUNTIFS('Raw Data'!$B:$B,$A8,'Raw Data'!$T:$T,"Underdog Covered") -> 255 | G8: =IF(F8=0,0,E8/F8) -> 0.50588235 | I8: 2010 | J8: 146 | K8: 4 | L8: 117 | M8: 267
A9: 2014 | B9: =COUNTIF('Raw Data'!$B:$B,$A9) -> 267 | C9: =COUNTIFS('Raw Data'!$B:$B,$A9,'Raw Data'!$U:$U,"Over") -> 123 | D9: =IF(B9=0,0,C9/B9) -> 0.46067416 | E9: =COUNTIFS('Raw Data'!$B:$B,$A9,'Raw Data'!$T:$T,"Favorite Covered") -> 67 | F9: =COUNTIFS('Raw Data'!$B:$B,$A9,'Raw Data'!$T:$T,"Favorite Covered")+COUNTIFS('Raw Data'!$B:$B,$A9,'Raw Data'!$T:$T,"Underdog Covered") -> 259 | G9: =IF(F9=0,0,E9/F9) -> 0.25868726 | I9: 2011 | J9: 130 | K9: 5 | L9: 132 | M9: 267
A10: 2015 | B10: =COUNTIF('Raw Data'!$B:$B,$A10) -> 267 | C10: =COUNTIFS('Raw Data'!$B:$B,$A10,'Raw Data'!$U:$U,"Over") -> 124 | D10: =IF(B10=0,0,C10/B10) -> 0.46441948 | E10: =COUNTIFS('Raw Data'!$B:$B,$A10,'Raw Data'!$T:$T,"Favorite Covered") -> 113 | F10: =COUNTIFS('Raw Data'!$B:$B,$A10,'Raw Data'!$T:$T,"Favorite Covered")+COUNTIFS('Raw Data'!$B:$B,$A10,'Raw Data'!$T:$T,"Underdog Covered") -> 253 | G10: =IF(F10=0,0,E10/F10) -> 0.44664032 | I10: 2012 | J10: 129 | K10: 5 | L10: 133 | M10: 267
A11: 2016 | B11: =COUNTIF('Raw Data'!$B:$B,$A11) -> 267 | C11: =COUNTIFS('Raw Data'!$B:$B,$A11,'Raw Data'!$U:$U,"Over") -> 140 | D11: =IF(B11=0,0,C11/B11) -> 0.52434457 | E11: =COUNTIFS('Raw Data'!$B:$B,$A11,'Raw Data'!$T:$T,"Favorite Covered") -> 137 | F11: =COUNTIFS('Raw Data'!$B:$B,$A11,'Raw Data'!$T:$T,"Favorite Covered")+COUNTIFS('Raw Data'!$B:$B,$A11,'Raw Data'!$T:$T,"Underdog Covered") -> 257 | G11: =IF(F11=0,0,E11/F11) -> 0.53307393 | I11: 2013 | J11: 133 | K11: 6 | L11: 128 | M11: 267
A12: 2017 | B12: =COUNTIF('Raw Data'!$B:$B,$A12) -> 267 | C12: =COUNTIFS('Raw Data'!$B:$B,$A12,'Raw Data'!$U:$U,"Over") -> 121 | D12: =IF(B12=0,0,C12/B12) -> 0.45318352 | E12: =COUNTIFS('Raw Data'!$B:$B,$A12,'Raw Data'!$T:$T,"Favorite Covered") -> 128 | F12: =COUNTIFS('Raw Data'!$B:$B,$A12,'Raw Data'!$T:$T,"Favorite Covered")+COUNTIFS('Raw Data'!$B:$B,$A12,'Raw Data'!$T:$T,"Underdog Covered") -> 254 | G12: =IF(F12=0,0,E12/F12) -> 0.50393701 | I12: 2014 | J12: 123 | K12: 4 | L12: 140 | M12: 267
I13: 2015 | J13: 124 | K13: 4 | L13: 139 | M13: 267
I14: 2016 | J14: 140 | K14: 5 | L14: 122 | M14: 267
I15: 2017 | J15: 121 | K15: 1 | L15: 145 | M15: 267
I16: Total Result | J16: 1046 | K16: 34 | L16: 1056 | M16: 2136
